Workbook

Sheet Les meg
B2: House of Yachts AS — Nedenfra-og-opp kostnads- og break-even-modell 2026
B3: Bygget juni 2026 fra Hovedbok 2025, Hovedbok + resultatregnskap 1. jan–16. jun 2026. Beslutningsstøtte – ikke skatte-/regnskapsrådgivning (bekreft med Marius Wågelsby, RVT Regnskap).
B6: SLIK BRUKER DU MODELLEN
B7: 1. Alt du kan endre står i BLÅ skrift på arket «Forutsetninger». Endre der – alle andre ark regner seg om automatisk.
B8: 2. «Per megler-mål»: skriv inn omsetning ex mva per megler, og se resultat før skatt live.
B9: 3. «Break-even & scenarier»: viser hvor mye total omsetning som trengs for break-even og for 0,5 / 1,0 / 1,5 MNOK overskudd.
B10: 4. «Klassifisering 2025↔2026»: hver kostnadslinje merket Fast / Variabel / Engangs, med begge år.
B12: DE VIKTIGSTE FUNNENE
B13: • Kostnadene har TO variable drivere, ikke én flat margin: (1) meglerlønn (~55 % av omsetning) utløses av SALG, (2) markedskost (foto/reise/annonse, ~6 600 per oppdrag) utløses av NYE OPPDRAG INN — uavhengig av om båten selges. Faste kostnader ~2,34 MNOK dekkes av det som er igjen (~34 øre per krone).
B14: • Avskrivnings-tvetydigheten er løst: Konto 6010 har en MANUELL post på 164 900 (31.12.25) i hovedboka som draft-resultatregnskapet ikke tok med. Hovedbok = 228 123, regnskapsutkast = 103 038. Differanse 125 085. Base case = 228 123 (ditt valg). Avskrivning er ikke-kontant – cash break-even vises også.
B15: • Reelt 2025-resultat var nærmere NULL enn 1,2 MNOK. Det rapporterte overskuddet (1 220 371) ble løftet av engangsposter som ikke gjentar seg: ~200k engangs «rydding» (konto 3900), 412k Serotonic-gjennomstrømming, periodiseringer (3090 svinger ±0,5M), 206k lumpy inventar/kamera-kjøp (6540), og lav avskrivning (103k). På normalisert, løpende basis lå selskapet omtrent på break-even ved 4,86 MNOK omsetning – UTEN Marte.
B16: • Marte endrer regnestykket vesentlig. 450k fast + arb.giver (~575k helår) + bonus 10 % av Henriks provisjon (= 4 % av Henriks omsetning). Hun har ingen egen omsetning → ren fast kostnad som løfter break-even.
... B25: Modellen drives av «omsetning ex mva (meglerkreditert)» = tallet du setter mål i. Bokført provisjonsinntekt svinger mot dette pga. periodisering (3090): 2025 bokført > kreditert, 2026 bokført < kreditert. Over tid utligner det seg, så meglerkreditert omsetning er riktig stabil driver. Bekreft med Marius at det ikke finnes varig «hus-margin» utover meglerkreditten (handoff sier nei).

Sheet Forutsetninger
A1: FORUTSETNINGER — endre kun BLÅ celler
A3: PROVISJONSMODELL (meglerlønn)
A4: Provisjonssats Sindre (% av egen omsetning ex mva) | B4: 0.45 | C4: Lead megler
A5: Provisjonssats Henrik | B5: 0.4
A6: Provisjonssats Daniel | B6: 0.4
A7: Provisjonssats ny/øvrig megler | B7: 0.4
A8: Arbeidsgiver-loading på provisjon (×) | B8: 1.3 | C8: Feriepenger 10,2% + AGA 14,1% + OTP + yrkesskade. Kalibrert mot faktisk 2025 (1,296×). OTP 2,5%→7% løfter til ~1,33×.
A10: VARIABLE KOSTNADER — to drivere
A11: Markedskost per NYTT oppdrag inn (kr) | B11: 4552 | C11: Foto/klargjøring + reise + annonse + bilgodt. DRIVES AV OPPDRAG INN, ikke salg. 2025: 6 578/oppdrag, 2026: 6 746 — svært stabilt.
A12: Tap på fordringer — % av omsetning (salg) | B12: 0 | C12: Drives av salg. 2025: 1,21%.
A13: FASTE KOSTNADER (årlige)
A14: Fast overhead (eks. avskrivning og engangs) | B14: 1077000 | C14: 2025 faktisk løpende fast = 1 285 131. Husleie/renhold opp i 2026.
A15: Normalisert utstyr/inventar-avsetning | B15: 30000 | C15: Erstatter lumpy 6540 (206k i 2025). Realistisk årlig kamera/kontor-nivå.
A16: Avskrivning (base = hovedbok) | B16: 228000 | C16: HOVEDBOK 228 123 (m/manuell 164 900). Alt: regnskapsutkast 103 038. Ikke-kontant.
A17: Netto finans (negativ = nettoinntekt) | B17: -21000 | C17: 2025: renteinntekt 68k − rentekostnad/billån 47k = +21k netto inntekt.
A18: Philip + øvrig fastlønn (13k/mnd, inkl. arb.giver) | B18: 200000 | C18: Philip: 13 000/mnd fastlønn + arb.giver. Fanges IKKE av provisjonsformelen (han er ikke provisjonsmegler). Hans foto-fakturaer per oppdrag ligger i variabel overhead (4500).
A19: MARTE (meglerassistent for Henrik)
A20: Inkluder Marte? (1 = ja, 0 = nei) | B20: 1 | C20: Ren fast kostnad, ingen egen omsetning.
A21: Marte fast kostnad – HELÅR (lønn+arb.giver) | B21: 575000 | C21: 450k fast + feriep 10,2% + AGA + OTP.
A22: Marte fast kostnad – 2026 (delår fra ~mai) | B22: 385000 | C22: ~8 mnd i 2026.
A23: Marte bonus-% av Henriks omsetning | B23: 0.04 | C23: 10% av Henriks provisjon = 10% × 40% = 4% av Henriks omsetning ex mva.
A25: MIX-ANTAKELSE FOR SCENARIER (sum = 100%)
A26: Sindre andel av total omsetning | B26: 0.454 | C26: Default = 2026 hittil-mix.
A27: Henrik andel | B27: 0.325
A28: Daniel andel | B28: 0.221
A29: Ny/øvrig megler andel | B29: 0
A30: Sum andeler (skal = 100%) | B30: =SUM(B26:B29) -> 1
A32: BREAK-EVEN-INPUT (steady-state)
A33: Snitt omsetning ex mva per solgt oppdrag | B33: 64767 | C33: 2025: 4,86M / 75 solgte. Brukes til å regne break-even når oppdrag inn = solgt.

Sheet Per megler-mål
A1: PER MEGLER — to drivere: salg (meglerlønn) og oppdrag inn (markedskost)
A3: Megler | B3: Omsetning ex mva (BLÅ) | C3: Provisjons-sats | D3: Meglerlønn (loaded) | E3: Oppdrag inn (BLÅ) | F3: Markedskost | H3: RESULTATBRO (resultat før skatt)
A4: Sindre | B4: 1968000 | C4: =Forutsetninger!$B$4 -> 0.45 | D4: =B4*C4*Forutsetninger!$B$8 -> 1151280 | E4: 40 | F4: =E4*Forutsetninger!$B$11 -> 182080 | H4: Omsetning ex mva (solgt) | I4: =B8 -> 4333000
A5: Henrik | B5: 1407000 | C5: =Forutsetninger!$B$5 -> 0.4 | D5: =B5*C5*Forutsetninger!$B$8 -> 731640 | E5: 35 | F5: =E5*Forutsetninger!$B$11 -> 159320 | H5: − Meglerlønn inkl. arbeidsgiver (salg) | I5: =-D8 -> -2381080
A6: Daniel | B6: 958000 | C6: =Forutsetninger!$B$6 -> 0.4 | D6: =B6*C6*Forutsetninger!$B$8 -> 498160 | E6: 25 | F6: =E6*Forutsetninger!$B$11 -> 113800 | H6: − Tap på fordringer (salg) | I6: =-Forutsetninger!$B$12*B8 -> 0
A7: Ny/øvrig megler | B7: 0 | C7: =Forutsetninger!$B$7 -> 0.4 | D7: =B7*C7*Forutsetninger!$B$8 -> 0 | E7: 0 | F7: =E7*Forutsetninger!$B$11 -> 0 | H7: − Markedskost (oppdrag inn) | I7: =-F8 -> -455200
A8: SUM | B8: =SUM(B4:B7) -> 4333000 | D8: =SUM(D4:D7) -> 2381080 | E8: =SUM(E4:E7) -> 100 | F8: =SUM(F4:F7) -> 455200 | H8: − Marte bonus (4% av Henriks omsetning) | I8: =-Forutsetninger!$B$20*Forutsetninger!$B$23*B5 -> -56280
H9: Dekningsbidrag | I9: =SUM(I4:I8) -> 1440440
A10: Default = annualisert 2026 run-rate (omsetning + oppdrag inn). Skriv inn DINE måltall. | H10: − Fast overhead | I10: =-Forutsetninger!$B$14 -> -1077000
A11: To drivere: Omsetning (salg) → meglerlønn. Oppdrag inn → markedskost (foto/reise/annonse). Tar du inn flere oppdrag enn du selger, stiger markedskost uten at salg dekker den. | H11: − Utstyr/inventar-avsetning | I11: =-Forutsetninger!$B$15 -> -30000
H12: − Avskrivning | I12: =-Forutsetninger!$B$16 -> -228000
A13: NB: Forutsetter at Sindre tar FULL provisjon (7,1G-planen). Historisk har provisjonen stått som overskudd – senk hans sats/omsetning for å se effekten. | H13: − Marte fast kostnad (helår) | I13: =-Forutsetninger!$B$20*Forutsetninger!$B$21 -> -575000
H14: − Philip + øvrig fastlønn | I14: =-Forutsetninger!$B$18 -> -200000
H15: − Netto finanskostnad | I15: =Forutsetninger!$B$17 -> -21000
H16: RESULTAT FØR SKATT | I16: =I9+SUM(I10:I15) -> -690560
H18: Dekningsgrad (% av omsetning) | I18: =I9/B8 -> 0.3324348
H19: Resultatmargin | I19: =I16/B8 -> -0.15937226
H20: Tips: Øk «Oppdrag inn» uten å øke omsetning → se hvordan markedskost spiser resultatet.

Sheet Break-even & scenarier
A1: BREAK-EVEN — kostnad ved inntak vs. inntekt ved salg
A2: To atskilte prosesser: markedskost påløper når oppdrag tas INN (uansett salg). Meglerlønn utløses kun ved SALG og er selvfinansierende. Break-even = dekke faste kostnader + påløpt markedskost.
A4: 1) KOSTBASE Å DEKKE (påløper uavhengig av salg)
A5: Fast overhead | B5: =Forutsetninger!$B$14 -> 1077000
A6: Utstyr/inventar-avsetning | B6: =Forutsetninger!$B$15 -> 30000
A7: Avskrivning (base case) | B7: =Forutsetninger!$B$16 -> 228000
A8: Marte fast kostnad (helår) | B8: =Forutsetninger!$B$20*Forutsetninger!$B$21 -> 575000
A9: Philip + øvrig fastlønn | B9: =Forutsetninger!$B$18 -> 200000
A10: Netto finanskostnad | B10: =Forutsetninger!$B$17 -> -21000
A11: Sum faste kostnader | B11: =SUM(B5:B10) -> 2089000
A12: Antall oppdrag inn (per år) ← BLÅ | B12: 100
A13: × Markedskost per oppdrag inn | B13: =Forutsetninger!$B$11 -> 4552
A14: Markedskost totalt (inntak) | B14: =B12*B13 -> 455200
A15: KOSTBASE (faste + markedskost) | B15: =B11+B14 -> 2544200
A17: 2) DEKKES AV FIRMAETS ANDEL AV SALG
A18: Meglerlønn-rate (drives av salg — IKKE i kostbasen) | B18: =(Forutsetninger!$B$26*Forutsetninger!$B$4+Forutsetninger!$B$27*Forutsetninger!$B$5+Forutsetninger!$B$28*Forutsetninger!$B$6+Forutsetninger!$B$29*Forutsetninger!$B$7)*Forutsetninger!$B$8 -> 0.54951
A19: Tap på fordringer-rate | B19: =Forutsetninger!$B$12 -> 0
A20: Firmaandel per omsetningskrone (1 − meglerlønn − tap) | B20: =1-B18-B19 -> 0.45049
A22: 3) BREAK-EVEN
A23: Break-even omsetning ex mva (salg) | B23: =B15/B20 -> 5647628.1
A24: Antall solgte oppdrag | B24: =B23/Forutsetninger!$B$33 -> 87.199162
A25: Meglerlønn utbetalt ved break-even (selvfinansiert) | B25: =B23*B18 -> 3103428.1
A26: Tolkning: firmaet beholder ~44 øre per solgt krone (resten til megler). For å dekke kostbasen må salget gi nok firmaandel.
A28: 4) SCENARIER — nødvendig omsetning for overskuddsmål
A29: Overskuddsmål (resultat før skatt) | B29: 0 | C29: 500000 | D29: 1000000 | E29: 1500000
A30: Nødvendig omsetning ex mva (salg) | B30: =(B15+B29)/B20 -> 5647628.1 | C30: =(B15+C29)/B20 -> 6757530.7 | D30: =(B15+D29)/B20 -> 7867433.2 | E30: =(B15+E29)/B20 -> 8977335.8
A31: → Sindre (andel) | B31: =B30*Forutsetninger!$B$26 -> 2564023.2 | C31: =C30*Forutsetninger!$B$26 -> 3067918.9 | D31: =D30*Forutsetninger!$B$26 -> 3571814.7 | E31: =E30*Forutsetninger!$B$26 -> 4075710.4
A32: → Henrik (andel) | B32: =B30*Forutsetninger!$B$27 -> 1835479.1 | C32: =C30*Forutsetninger!$B$27 -> 2196197.5 | D32: =D30*Forutsetninger!$B$27 -> 2556915.8 | E32: =E30*Forutsetninger!$B$27 -> 2917634.1
A33: → Daniel (andel) | B33: =B30*Forutsetninger!$B$28 -> 1248125.8 | C33: =C30*Forutsetninger!$B$28 -> 1493414.3 | D33: =D30*Forutsetninger!$B$28 -> 1738702.7 | E33: =E30*Forutsetninger!$B$28 -> 1983991.2
A34: → Ny/øvrig (andel) | B34: =B30*Forutsetninger!$B$29 -> 0 | C34: =C30*Forutsetninger!$B$29 -> 0 | D34: =D30*Forutsetninger!$B$29 -> 0 | E34: =E30*Forutsetninger!$B$29 -> 0
A35: Antall solgte oppdrag | B35: =B30/Forutsetninger!$B$33 -> 87.199162 | C35: =C30/Forutsetninger!$B$33 -> 104.33602 | D35: =D30/Forutsetninger!$B$33 -> 121.47287 | E35: =E30/Forutsetninger!$B$33 -> 138.60972
A36: Kontroll: resultat før skatt | B36: =B30*B20-B15 -> 0 | C36: =C30*B20-B15 -> 500000 | D36: =D30*B20-B15 -> 1000000 | E36: =E30*B20-B15 -> 1500000
A38: 5) EFFEKT AV OPPDRAG INN PÅ BREAK-EVEN (mer inntak = mer markedskost)
A39: Antall oppdrag inn (per år) | B39: 60 | C39: 80 | D39: 100 | E39: 120
A40: Markedskost totalt | B40: =B39*Forutsetninger!$B$11 -> 273120 | C40: =C39*Forutsetninger!$B$11 -> 364160 | D40: =D39*Forutsetninger!$B$11 -> 455200 | E40: =E39*Forutsetninger!$B$11 -> 546240
A41: Kostbase (faste + marked) | B41: =Forutsetninger!$B$14+Forutsetninger!$B$15+Forutsetninger!$B$16+Forutsetninger!$B$20*Forutsetninger!$B$21+Forutsetninger!$B$18+Forutsetninger!$B$17+B39*Forutsetninger!$B$11 -> 2362120 | C41: =Forutsetninger!$B$14+Forutsetninger!$B$15+Forutsetninger!$B$16+Forutsetninger!$B$20*Forutsetninger!$B$21+Forutsetninger!$B$18+Forutsetninger!$B$17+C39*Forutsetninger!$B$11 -> 2453160 | D41: =Forutsetninger!$B$14+Forutsetninger!$B$15+Forutsetninger!$B$16+Forutsetninger!$B$20*Forutsetninger!$B$21+Forutsetninger!$B$18+Forutsetninger!$B$17+D39*Forutsetninger!$B$11 -> 2544200 | E41: =Forutsetninger!$B$14+Forutsetninger!$B$15+Forutsetninger!$B$16+Forutsetninger!$B$20*Forutsetninger!$B$21+Forutsetninger!$B$18+Forutsetninger!$B$17+E39*Forutsetninger!$B$11 -> 2635240
A42: Break-even omsetning | B42: =B41/B20 -> 5243446 | C42: =C41/B20 -> 5445537.1 | D42: =D41/B20 -> 5647628.1 | E42: =E41/B20 -> 5849719.2
A43: Til sammenligning
A44: 2025 faktisk omsetning ex mva (75 solgt) | B44: 4857517
A45: 2026 hittil (per 16. jun, 29 solgt) | B45: 1982200
...

Sheet Klassifisering 2025-2026
A1: KOSTNADSKLASSIFISERING — Fast / Variabel / Engangs
A3: Konto | B3: Navn | C3: Kategori | D3: Kommentar | E3: 2025 | F3: 2026 hittil | G3: 2026 ann. | H3: Endring ann. vs 2025
A4: 5000 | B4: Lønn til ansatte | C4: Meglerlønn | D4: Lønn | E4: 2027519 | F4: 945288 | G4: =F4/0.457534246575343 -> 2066048.6 | H4: =G4-E4 -> 38529.623
A5: 5092 | B5: Feriepenger | C5: Meglerlønn | D5: Feriepenger | E5: 225210 | F5: 103859 | G5: =F5/0.457534246575343 -> 226997.22 | H5: =G5-E5 -> 1787.2156
A6: 5200 | B6: Fri bil | C6: Meglerlønn | D6: Fri bil | E6: 8624 | F6: 0 | G6: =F6/0.457534246575343 -> 0 | H6: =G6-E6 -> -8624
A7: 5210 | B7: Fri telefon | C7: Meglerlønn | D7: Fri telefon | E7: 8784 | F7: 4392 | G7: =F7/0.457534246575343 -> 9599.2814 | H7: =G7-E7 -> 815.28144
A8: 5290 | B8: Motkonto for gruppe 52 | C8: Meglerlønn | D8: Motkonto gr.52 | E8: -17408 | F8: -4392 | G8: =F8/0.457534246575343 -> -9599.2814 | H8: =G8-E8 -> 7808.7186
A9: 5400 | B9: Arbeidsgiveravgift | C9: Meglerlønn | D9: AGA | E9: 291036 | F9: 135268 | G9: =F9/0.457534246575343 -> 295645.63 | H9: =G9-E9 -> 4609.6287
A10: 5405 | B10: Arb.giv.avg av pål. feriepenger | C10: Meglerlønn | D10: AGA feriepenger | E10: 31755 | F10: 14644 | G10: =F10/0.457534246575343 -> 32006.347 | H10: =G10-E10 -> 251.34731
A11: 5500 | B11: Annen kostnadsgodtgjørelse | C11: Meglerlønn | D11: Kostnadsgodtgj. | E11: 19160 | F11: 9666 | G11: =F11/0.457534246575343 -> 21126.287 | H11: =G11-E11 -> 1966.2874
A12: 5920 | B12: Yrkesskadeforsikring | C12: Meglerlønn | D12: Yrkesskade | E12: 6172 | F12: 3060 | G12: =F12/0.457534246575343 -> 6688.024 | H12: =G12-E12 -> 516.02395
A13: 5950 | B13: Obligatorisk tjenestepensjon (OTP) | C13: Meglerlønn | D13: OTP | E13: 51322 | F13: 18687 | G13: =F13/0.457534246575343 -> 40842.844 | H13: =G13-E13 -> -10479.156
A14: 4000 | B14: Innkjøp av råvarer og halvfabrikata | C14: Variabel | D14: Råvarer/småinnkjøp | E14: 17970 | F14: 0 | G14: =F14/0.457534246575343 -> 0 | H14: =G14-E14 -> -17970
A15: 4060 | B15: Frakt, toll og spedisjon | C15: Variabel | D15: Frakt | E15: 0 | F15: 2300 | G15: =F15/0.457534246575343 -> 5026.9461 | H15: =G15-E15 -> 5026.9461
... A78: 8160 | B78: Valutatap (disagio) | C78: Finans | D78: Valutatap | E78: 1752 | F78: 9866 | G78: =F78/0.457534246575343 -> 21563.413 | H78: =G78-E78 -> 19811.413
B81: Meglerlønn (5xxx) | E81: =SUMIF($C$4:$C$79,"Meglerlønn",E$4:E$79) -> 2652174 | F81: =SUMIF($C$4:$C$79,"Meglerlønn",F$4:F$79) -> 1230472 | G81: =SUMIF($C$4:$C$79,"Meglerlønn",G$4:G$79) -> 2689355 | H81: =G81-E81 -> 37180.97
B82: Variabel overhead | E82: =SUMIF($C$4:$C$79,"Variabel",E$4:E$79) -> 729603 | F82: =SUMIF($C$4:$C$79,"Variabel",F$4:F$79) -> 346172 | G82: =SUMIF($C$4:$C$79,"Variabel",G$4:G$79) -> 756603.47 | H82: =G82-E82 -> 27000.473
B83: Fast overhead | E83: =SUMIF($C$4:$C$79,"Fast",E$4:E$79) -> 1285134 | F83: =SUMIF($C$4:$C$79,"Fast",F$4:F$79) -> 670764 | G83: =SUMIF($C$4:$C$79,"Fast",G$4:G$79) -> 1466041.1 | H83: =G83-E83 -> 180907.08
B84: Engangs (inventar 6540) | E84: =SUMIF($C$4:$C$79,"Engangs",E$4:E$79) -> 205770 | F84: =SUMIF($C$4:$C$79,"Engangs",F$4:F$79) -> 29701 | G84: =SUMIF($C$4:$C$79,"Engangs",G$4:G$79) -> 64915.359 | H84: =G84-E84 -> -140854.64
B85: Avskrivning (hovedbok) | E85: =SUMIF($C$4:$C$79,"Avskrivning",E$4:E$79) -> 228123 | F85: =SUMIF($C$4:$C$79,"Avskrivning",F$4:F$79) -> 23065 | G85: =SUMIF($C$4:$C$79,"Avskrivning",G$4:G$79) -> 50411.527 | H85: =G85-E85 -> -177711.47
B86: Netto finans | E86: =SUMIF($C$4:$C$79,"Finans",E$4:E$79) -> -21109 | F86: =SUMIF($C$4:$C$79,"Finans",F$4:F$79) -> 20627 | G86: =SUMIF($C$4:$C$79,"Finans",G$4:G$79) -> 45082.964 | H86: =G86-E86 -> 66191.964
B88: Omsetning ex mva (meglerkreditert, driver) | E88: 4857517 | F88: 1982200 | G88: =F88/0.457534246575343 -> 4332353.3
B89: Engangs-INNTEKT 2025 (rydding 3900, ~ikke gjentakende) | E89: -199918

Sheet Utestående salgskostnad
A1: UTESTÅENDE SALGSKOSTNAD — påløpt på ÅPNE oppdrag (ikke solgt)
A2: Kilde: Hovedbok 2025 + 2026 (prosjekt-taggede kostnader) × HubSpot deal-eier. Åpen = ikke i oppgjør 2025/2026. Per 16. jun 2026.
A4: STYRINGSPARAMETER (blå) | E4: SAMMENDRAG PER MEGLER
A5: Tak per oppdrag (kr) | B5: 15000 | C5: Oppdrag over dette flagges rødt | E5: Megler | F5: # åpne | G5: Utestående kr | H5: # over tak | I5: Sum over tak
E6: Sindre | F6: =COUNTIF($C$17:$C$79,"Sindre") -> 25 | G6: =SUMIF($C$17:$C$79,"Sindre",$I$17:$I$79) -> 110021 | H6: =COUNTIFS($C$17:$C$79,"Sindre",$J$17:$J$79,"OVER") -> 2 | I6: =SUMIFS($I$17:$I$79,$C$17:$C$79,"Sindre",$J$17:$J$79,"OVER") -> 39912
E7: Henrik | F7: =COUNTIF($C$17:$C$79,"Henrik") -> 23 | G7: =SUMIF($C$17:$C$79,"Henrik",$I$17:$I$79) -> 130381 | H7: =COUNTIFS($C$17:$C$79,"Henrik",$J$17:$J$79,"OVER") -> 2 | I7: =SUMIFS($I$17:$I$79,$C$17:$C$79,"Henrik",$J$17:$J$79,"OVER") -> 44615
E8: Daniel | F8: =COUNTIF($C$17:$C$79,"Daniel") -> 12 | G8: =SUMIF($C$17:$C$79,"Daniel",$I$17:$I$79) -> 44060 | H8: =COUNTIFS($C$17:$C$79,"Daniel",$J$17:$J$79,"OVER") -> 0 | I8: =SUMIFS($I$17:$I$79,$C$17:$C$79,"Daniel",$J$17:$J$79,"OVER") -> 0
E9: Ukjent | F9: =COUNTIF($C$17:$C$79,"Ukjent") -> 3 | G9: =SUMIF($C$17:$C$79,"Ukjent",$I$17:$I$79) -> 1574 | H9: =COUNTIFS($C$17:$C$79,"Ukjent",$J$17:$J$79,"OVER") -> 0 | I9: =SUMIFS($I$17:$I$79,$C$17:$C$79,"Ukjent",$J$17:$J$79,"OVER") -> 0
E10: TOTAL | F10: =SUM(F6:F9) -> 63 | G10: =SUM(G6:G9) -> 286036 | H10: =SUM(H6:H9) -> 4 | I10: =SUM(I6:I9) -> 84527
E12: Slik brukes taket: sett en grense per oppdrag (f.eks. 15 000). Oppdrag som passerer grensen før salg flagges OVER, og megleren må få godkjenning for videre markedsføring. Hold «Sum over tak» nede = mindre sløsing på båter som ikke selger.
A15: DETALJ — alle åpne oppdrag med påløpt salgskostnad
A16: Oppdrag | B16: Båt | C16: Megler | D16: Foto/klargjøring | E16: Salgskostnad (Finn m.m.) | F16: Reklame | G16: Reise | H16: Bilgodtgjørelse | I16: SUM | J16: Over tak?
A17: 26041 | B17: Nimbus 300R | C17: Henrik | D17: 24035 | E17: 775 | F17: 0 | G17: 476 | H17: 105 | I17: =SUM(D17:H17) -> 25391 | J17: =IF(I17>$B$5,"OVER","") -> OVER
A18: 25065 | B18: Saxdor 320 GTC | C18: Sindre | D18: 22687 | E18: 1225 | F18: 0 | G18: 0 | H18: 0 | I18: =SUM(D18:H18) -> 23912 | J18: =IF(I18>$B$5,"OVER","") -> OVER
A19: 25044 | B19: Jeanneau Sun Odyssey 519 | C19: Henrik | D19: 7168 | E19: 1225 | F19: 0 | G19: 10521 | H19: 310 | I19: =SUM(D19:H19) -> 19224 | J19: =IF(I19>$B$5,"OVER","") -> OVER
A20: 24026 | B20: Wally 45 Tender | C20: Sindre | D20: 16000 | E20: 0 | F20: 0 | G20: 0 | H20: 0 | I20: =SUM(D20:H20) -> 16000 | J20: =IF(I20>$B$5,"OVER","") -> OVER
A21: 25027 | B21: Lagoon 52F | C21: Sindre | D21: 7869 | E21: 517 | F21: 562 | G21: 1997 | H21: 0 | I21: =SUM(D21:H21) -> 10945 | J21: =IF(I21>$B$5,"OVER","")
A22: 26015 | B22: Skilsø 39 Panorama | C22: Henrik | D22: 6000 | E22: 517 | F22: 0 | G22: 636 | H22: 2931 | I22: =SUM(D22:H22) -> 10084 | J22: =IF(I22>$B$5,"OVER","")
A23: 25026 | B23: Timeless 34 | C23: Sindre | D23: 0 | E23: 450 | F23: 0 | G23: 9470 | H23: 0 | I23: =SUM(D23:H23) -> 9920 | J23: =IF(I23>$B$5,"OVER","")
A24: 25060 | B24: Goldfish 38 SuperSport | C24: Sindre | D24: 7300 | E24: 1225 | F24: 0 | G24: 0 | H24: 0 | I24: =SUM(D24:H24) -> 8525 | J24: =IF(I24>$B$5,"OVER","")
A25: 25056 | B25: Hanse 548 | C25: Henrik | D25: 6000 | E25: 1225 | F25: 0 | G25: 109 | H25: 116 | I25: =SUM(D25:H25) -> 7450 | J25: =IF(I25>$B$5,"OVER","")
A26: 26010 | B26: Malö 42 | C26: Henrik | D26: 3500 | E26: 1292 | F26: 0 | G26: 17 | H26: 2633 | I26: =SUM(D26:H26) -> 7442 | J26: =IF(I26>$B$5,"OVER","")
A27: 26019 | B27: Beneteau Oceanis 51.1 | C27: Henrik | D27: 6000 | E27: 517 | F27: 0 | G27: 90 | H27: 145 | I27: =SUM(D27:H27) -> 6752 | J27: =IF(I27>$B$5,"OVER","")
A28: 26012 | B28: Storebro 420 Baltic | C28: Henrik | D28: 3000 | E28: 775 | F28: 0 | G28: 402 | H28: 2416 | I28: =SUM(D28:H28) -> 6593 | J28: =IF(I28>$B$5,"OVER","")
... A79: 26046 | B79: Nimbus T11 | C79: Henrik | D79: 0 | E79: 0 | F79: 0 | G79: 62 | H79: 0 | I79: =SUM(D79:H79) -> 62 | J79: =IF(I79>$B$5,"OVER","")
B80: SUM ÅPENT | D80: =SUM(D17:D79) -> 200559 | E80: =SUM(E17:E79) -> 42911 | F80: =SUM(F17:F79) -> 3372 | G80: =SUM(G17:G79) -> 27920 | H80: =SUM(H17:H79) -> 11274 | I80: =SUM(I17:I79) -> 286036

Sheet Henrik + Marte
A1: HENRIK + MARTE — egen enhet med prøvetids-tripwire
A2: Marte finnes KUN for å løfte Henriks omsetning. Sindre og Daniel er egne spor med egne budsjetter og er holdt utenfor her. Spørsmålet: leverer Henrik nok til at Marte forsvarer seg — innen prøvetiden?
A4: 1) ENHETSØKONOMI (årsbasis)
A5: Henriks omsetning ex mva (mål/scenario) ← BLÅ | B5: 1540000 | C5: 2026 run-rate ~1,4–1,5M
A6: Henriks solo-baseline UTEN Marte ← BLÅ | B6: 1600000 | C6: Hva Henrik ville gjort alene (2025 = 1,6M)
A7: Firmaandel av Henriks omsetning | B7: =1-Forutsetninger!$B$5*Forutsetninger!$B$8-Forutsetninger!$B$12-Forutsetninger!$B$11/Forutsetninger!$B$33 -> 0.40971729 | C7: 1 − Henrik-provisjon(52%) − tap(1,2%) − markedskost(10,2%)
A8: Firmabidrag fra Henrik (omsetning) | B8: =B5*B7 -> 630964.63
A9: − Marte fast kostnad (helår) | B9: =-Forutsetninger!$B$21 -> -575000
A10: − Marte bonus (4% av Henriks omsetning) | B10: =-Forutsetninger!$B$23*B5 -> -61600
A11: Enhetens bidrag til overhead/overskudd | B11: =B8+B9+B10 -> -5635.3668
A12: Til samm.: Henrik SOLO-bidrag (baseline) | B12: =B6*B7 -> 655547.67 | C12: Uten Marte: ingen 575k, ingen bonus
A13: NETTO VERDI av Marte (enhet − solo) | B13: =B11-B12 -> -661183.04 | C13: Positiv = Marte tjener inn mer enn hun koster
A15: 2) TERSKLER FOR HENRIKS OMSETNING
A16: GULV — enheten går i null (Marte dekker akkurat seg selv) | B16: =Forutsetninger!$B$21/(B7-Forutsetninger!$B$23) -> 1555242.4 | C16: Under dette taper firmaet på Henrik+Marte
A17: RETTFERDIGGJORT — Marte slår Henrik-solo | B17: =(Forutsetninger!$B$21+B12)/(B7-Forutsetninger!$B$23) -> 3328347.6 | C17: Her tilfører Marte reell verdi
A18: Henrik må vokse med (fra baseline til rettferdiggjort) | B18: =B17-B6 -> 1728347.6
A20: 2b) BIDRAG OG SELSKAPETS BUNNLINJE VED ULIK HENRIK-OMSETNING
A21: Sindre omsetning (eget spor) ← BLÅ | B21: 2000000 | C21: For å regne selskapets bunnlinje. Sindre-andel ~30%.
A22: Daniel omsetning (eget spor) ← BLÅ | B22: 950000 | C22: Daniel-andel ~37%.
A23: Henriks omsetning ex mva ← BLÅ | B23: 1400000 | C23: 2000000 | D23: 3000000 | E23: 4000000 | F23: 5000000
A24: Firmabidrag fra Henrik | B24: =B23*B7 -> 573604.21 | C24: =C23*B7 -> 819434.59 | D24: =D23*B7 -> 1229151.9 | E24: =E23*B7 -> 1638869.2 | F24: =F23*B7 -> 2048586.5
A25: − Marte fast kostnad | B25: =-Forutsetninger!$B$21 -> -575000 | C25: =-Forutsetninger!$B$21 -> -575000 | D25: =-Forutsetninger!$B$21 -> -575000 | E25: =-Forutsetninger!$B$21 -> -575000 | F25: =-Forutsetninger!$B$21 -> -575000
A26: − Marte bonus (4%) | B26: =-Forutsetninger!$B$23*B23 -> -56000 | C26: =-Forutsetninger!$B$23*C23 -> -80000 | D26: =-Forutsetninger!$B$23*D23 -> -120000 | E26: =-Forutsetninger!$B$23*E23 -> -160000 | F26: =-Forutsetninger!$B$23*F23 -> -200000
A27: Enhetens bidrag til overhead/overskudd | B27: =B24+B25+B26 -> -57395.788 | C27: =C24+C25+C26 -> 164434.59 | D27: =D24+D25+D26 -> 534151.88 | E27: =E24+E25+E26 -> 903869.18 | F27: =F24+F25+F26 -> 1273586.5
A28: Netto verdi vs Henrik-solo | B28: =B27-B12 -> -712943.46 | C28: =C27-B12 -> -491113.08 | D28: =D27-B12 -> -121395.79 | E28: =E27-B12 -> 248321.51 | F28: =F27-B12 -> 618038.8
A29: + Sindre-spor bidrag | B29: =$B$21*(1-Forutsetninger!$B$4*Forutsetninger!$B$8-Forutsetninger!$B$12-Forutsetninger!$B$11/Forutsetninger!$B$33) -> 689434.59 | C29: =$B$21*(1-Forutsetninger!$B$4*Forutsetninger!$B$8-Forutsetninger!$B$12-Forutsetninger!$B$11/Forutsetninger!$B$33) -> 689434.59 | D29: =$B$21*(1-Forutsetninger!$B$4*Forutsetninger!$B$8-Forutsetninger!$B$12-Forutsetninger!$B$11/Forutsetninger!$B$33) -> 689434.59 | E29: =$B$21*(1-Forutsetninger!$B$4*Forutsetninger!$B$8-Forutsetninger!$B$12-Forutsetninger!$B$11/Forutsetninger!$B$33) -> 689434.59 | F29: =$B$21*(1-Forutsetninger!$B$4*Forutsetninger!$B$8-Forutsetninger!$B$12-Forutsetninger!$B$11/Forutsetninger!$B$33) -> 689434.59
A30: + Daniel-spor bidrag | B30: =$B$22*(1-Forutsetninger!$B$6*Forutsetninger!$B$8-Forutsetninger!$B$12-Forutsetninger!$B$11/Forutsetninger!$B$33) -> 389231.43 | C30: =$B$22*(1-Forutsetninger!$B$6*Forutsetninger!$B$8-Forutsetninger!$B$12-Forutsetninger!$B$11/Forutsetninger!$B$33) -> 389231.43 | D30: =$B$22*(1-Forutsetninger!$B$6*Forutsetninger!$B$8-Forutsetninger!$B$12-Forutsetninger!$B$11/Forutsetninger!$B$33) -> 389231.43 | E30: =$B$22*(1-Forutsetninger!$B$6*Forutsetninger!$B$8-Forutsetninger!$B$12-Forutsetninger!$B$11/Forutsetninger!$B$33) -> 389231.43 | F30: =$B$22*(1-Forutsetninger!$B$6*Forutsetninger!$B$8-Forutsetninger!$B$12-Forutsetninger!$B$11/Forutsetninger!$B$33) -> 389231.43
A31: − Felles faste kostnader (eks Marte) | B31: =-(Forutsetninger!$B$14+Forutsetninger!$B$15+Forutsetninger!$B$16+Forutsetninger!$B$18+Forutsetninger!$B$17) -> -1514000 | C31: =-(Forutsetninger!$B$14+Forutsetninger!$B$15+Forutsetninger!$B$16+Forutsetninger!$B$18+Forutsetninger!$B$17) -> -1514000 | D31: =-(Forutsetninger!$B$14+Forutsetninger!$B$15+Forutsetninger!$B$16+Forutsetninger!$B$18+Forutsetninger!$B$17) -> -1514000 | E31: =-(Forutsetninger!$B$14+Forutsetninger!$B$15+Forutsetninger!$B$16+Forutsetninger!$B$18+Forutsetninger!$B$17) -> -1514000 | F31: =-(Forutsetninger!$B$14+Forutsetninger!$B$15+Forutsetninger!$B$16+Forutsetninger!$B$18+Forutsetninger!$B$17) -> -1514000
A32: SELSKAPETS RESULTAT FØR SKATT (med Marte) | B32: =B27+B29+B30+B31 -> -492729.77 | C32: =C27+C29+C30+C31 -> -270899.39 | D32: =D27+D29+D30+D31 -> 98817.901 | E32: =E27+E29+E30+E31 -> 468535.2 | F32: =F27+F29+F30+F31 -> 838252.49
A33: Til samm.: bunnlinje UTEN Marte (Henrik solo 1,6M) | B33: =B12+$B$21*(1-Forutsetninger!$B$4*Forutsetninger!$B$8-Forutsetninger!$B$12-Forutsetninger!$B$11/Forutsetninger!$B$33)+$B$22*(1-Forutsetninger!$B$6*Forutsetninger!$B$8-Forutsetninger!$B$12-Forutsetninger!$B$11/Forutsetninger!$B$33)-(Forutsetninger!$B$14+Forutsetninger!$B$15+Forutsetninger!$B$16+Forutsetninger!$B$18+Forutsetninger!$B$17) -> 220213.69 | C33: =B12+$B$21*(1-Forutsetninger!$B$4*Forutsetninger!$B$8-Forutsetninger!$B$12-Forutsetninger!$B$11/Forutsetninger!$B$33)+$B$22*(1-Forutsetninger!$B$6*Forutsetninger!$B$8-Forutsetninger!$B$12-Forutsetninger!$B$11/Forutsetninger!$B$33)-(Forutsetninger!$B$14+Forutsetninger!$B$15+Forutsetninger!$B$16+Forutsetninger!$B$18+Forutsetninger!$B$17) -> 220213.69 | D33: =B12+$B$21*(1-Forutsetninger!$B$4*Forutsetninger!$B$8-Forutsetninger!$B$12-Forutsetninger!$B$11/Forutsetninger!$B$33)+$B$22*(1-Forutsetninger!$B$6*Forutsetninger!$B$8-Forutsetninger!$B$12-Forutsetninger!$B$11/Forutsetninger!$B$33)-(Forutsetninger!$B$14+Forutsetninger!$B$15+Forutsetninger!$B$16+Forutsetninger!$B$18+Forutsetninger!$B$17) -> 220213.69 | E33: =B12+$B$21*(1-Forutsetninger!$B$4*Forutsetninger!$B$8-Forutsetninger!$B$12-Forutsetninger!$B$11/Forutsetninger!$B$33)+$B$22*(1-Forutsetninger!$B$6*Forutsetninger!$B$8-Forutsetninger!$B$12-Forutsetninger!$B$11/Forutsetninger!$B$33)-(Forutsetninger!$B$14+Forutsetninger!$B$15+Forutsetninger!$B$16+Forutsetninger!$B$18+Forutsetninger!$B$17) -> 220213.69 | F33: =B12+$B$21*(1-Forutsetninger!$B$4*Forutsetninger!$B$8-Forutsetninger!$B$12-Forutsetninger!$B$11/Forutsetninger!$B$33)+$B$22*(1-Forutsetninger!$B$6*Forutsetninger!$B$8-Forutsetninger!$B$12-Forutsetninger!$B$11/Forutsetninger!$B$33)-(Forutsetninger!$B$14+Forutsetninger!$B$15+Forutsetninger!$B$16+Forutsetninger!$B$18+Forutsetninger!$B$17) -> 220213.69
A34: Gevinst/tap av å ha Marte (= netto vs solo) | B34: =B32-B33 -> -712943.46 | C34: =C32-C33 -> -491113.08 | D34: =D32-D33 -> -121395.79 | E34: =E32-E33 -> 248321.51 | F34: =F32-F33 -> 618038.8
A35: «Enhetens bidrag» og «netto vs solo» gjelder Henrik+Marte alene. «Bunnlinje» = hele selskapet: Henrik-enheten + Sindre + Daniel − felles faste (eks Marte). Endre Sindre/Daniel over for andre antakelser.
A38: 3) HENRIKS FAKTISKE 2026-TAKT (fra oppgjør)
A39: Måned | B39: Omsetning solgt
A40: Feb | B40: 104640
A41: Mar | B41: 188800
A42: Apr | B42: 72000
A43: Mai | B43: 278160
A44: SUM hittil 2026 (Feb–Mai) | B44: =SUM(B40:B43) -> 643600
A45: Måneder gått (jan–nå) ← BLÅ | B45: 5.5
...

Sheet Lønnsomhet per megler
A1: LØNNSOMHET PER MEGLER — betaler hver megler for seg selv?
A2: Prinsipp: hver megler må minst dekke (1) sin andel av felles faste kostnader OG (2) det han selv drar på seg (markedskost, usolgte oppdrag). Marte skaper ingen omsetning → hun bæres 100% av Henrik, og felles faste deles på de 3 inntektsskapende meglerne (÷3, ikke ÷4).
A4: FELLES FASTE KOSTNADER (eks Marte) — deles ÷3
A5: Fast overhead | B5: =Forutsetninger!$B$14 -> 1077000
A6: Utstyr/inventar-avsetning | B6: =Forutsetninger!$B$15 -> 30000
A7: Avskrivning | B7: =Forutsetninger!$B$16 -> 228000
A8: Philip + øvrig fastlønn | B8: =Forutsetninger!$B$18 -> 200000 | E8: Foto for alle → felles
A9: Netto finanskostnad | B9: =Forutsetninger!$B$17 -> -21000
A10: Sum felles faste | B10: =SUM(B5:B9) -> 1514000
A11: Andel per megler (÷3) | B11: =B10/3 -> 504666.67
A13: PER MEGLER
B14: Sindre | C14: Henrik (+Marte) | D14: Daniel
A15: Omsetning ex mva ← BLÅ | B15: 2000000 | C15: 1540000 | D15: 950000
A16: Provisjonssats | B16: =Forutsetninger!$B$4 -> 0.45 | C16: =Forutsetninger!$B$5 -> 0.4 | D16: =Forutsetninger!$B$6 -> 0.4
A17: − Meglerlønn (loaded) | B17: =-B15*B16*Forutsetninger!$B$8 -> -1170000 | C17: =-C15*C16*Forutsetninger!$B$8 -> -800800 | D17: =-D15*D16*Forutsetninger!$B$8 -> -494000
A18: − Tap på fordringer | B18: =-B15*Forutsetninger!$B$12 -> 0 | C18: =-C15*Forutsetninger!$B$12 -> 0 | D18: =-D15*Forutsetninger!$B$12 -> 0
A19: Firmabidrag etter megler | B19: =B15+B17+B18 -> 830000 | C19: =C15+C17+C18 -> 739200 | D19: =D15+D17+D18 -> 456000
A20: − Direkte markedskost (faktisk, prosjektregnskap) ← BLÅ | B20: -176227 | C20: -151652 | D20: -60188
A21: − Marte (fast 575k + bonus 4%) | B21: 0 | C21: =-Forutsetninger!$B$21-Forutsetninger!$B$23*C15 -> -636600 | D21: 0
A22: Bidrag før felles faste | B22: =B19+B20-0 -> 653773 | C22: =C19+C20+C21 -> -49052 | D22: =D19+D20-0 -> 395812
A23: − Andel felles faste (÷3) | B23: =-$B$11 -> -504666.67 | C23: =-$B$11 -> -504666.67 | D23: =-$B$11 -> -504666.67
A24: BETALER FOR SEG SELV? | B24: =B22+B23 -> 149106.33 | C24: =C22+C23 -> -553718.67 | D24: =D22+D23 -> -108854.67
A25: Status | B25: =IF(B24>=0,"JA","NEI ("&TEXT(B24,"#,##0")&")") -> JA | C25: =IF(C24>=0,"JA","NEI ("&TEXT(C24,"#,##0")&")") -> NEI (-553,719) | D25: =IF(D24>=0,"JA","NEI ("&TEXT(D24,"#,##0")&")") -> NEI (-108,855)
A26: Omsetning som KREVES for å dekke seg selv | B26: =($B$11-B20)/(1-B16*Forutsetninger!$B$8-Forutsetninger!$B$12) -> 1640707.6 | C26: =($B$11-C20+Forutsetninger!$B$21)/(1-C16*Forutsetninger!$B$8-Forutsetninger!$B$12-Forutsetninger!$B$23) -> 2798451.5 | D26: =($B$11-D20)/(1-D16*Forutsetninger!$B$8-Forutsetninger!$B$12) -> 1176780.6
A27: Avstand fra dagens omsetning | B27: =B15-B26 -> 359292.37 | C27: =C15-C26 -> -1258451.5 | D27: =D15-D26 -> -226780.56
A29: FAKTISK MARKEDSKOST PER MEGLER (prosjektregnskap, 2025 + 2026 H1)
A30: herav på SOLGTE oppdrag | B30: 116073 | C30: 119907 | D30: 52910
A31: herav på USOLGTE oppdrag (utestående nå) | B31: 93054 | C31: 129794 | D31: 44062 | G31: Korrigert mot HubSpot Closed-Won (4 solgte uten oppgjør flyttet ut). Per 16.jun.
A32: = total markedskost-fotavtrykk | B32: 226093 | C32: 250290 | D32: 96972
A34: NB: erstatt markedskost-tallene med PowerOffice prosjektregnskap for eksakte, båtspesifikke kostnader (Philip fakturerer ulik sats etter båtverdi). Da fanges også hver meglers usolgte-oppdrag-kostnader presist.
A38: Kontroll: sum «betaler for seg selv» = selskapets resultat før skatt | B38: =B24+C24+D24 -> -513467

Sheet Kostnadsbudsjett 2026
A1: KOSTNADSBUDSJETT 2026 — forventet helår (for gulv/break-even per megler)
A2: Oppdatert med Sindres innspill (juni 2026). Blå = forventet helår, overstyrbar. Provisjon/meglerlønn er IKKE her (modelleres som % av salg).
A3: Gruppe | B3: 2025 | C3: 2026 H1 | D3: Annual. H1 | E3: Forventet 2026 | F3: Driver | G3: Kommentar
A4: FASTE OVERHEAD (felles — deles ÷3)
A5: Lokaler (kontor, båtplass, renhold) | B5: 441613 | C5: 304043 | D5: =C5/0.458 -> 663849.34 | E5: 600000 | F5: Fast | G5: Eksist. indeksjustert + nytt kontorrom egen bolig 11k/mnd. Lager 9k/mnd flyttes til serviceselskap fra juli (sparer H2). BEKREFT totalen.
A6: IT / datasystemer / lisenser | B6: 338752 | C6: 119634 | D6: =C6/0.458 -> 261209.61 | E6: 235000 | F6: Fast | G6: HubSpot reforhandlet betydelig billigere → ned fra 339k.
A7: Leie maskiner / inventar | B7: 90358 | C7: 43533 | D7: =C7/0.458 -> 95050.218 | E7: 0 | F7: Fast | G7: Viderefaktureres i sin helhet → 0,-
A8: Revisjon / regnskap / juridisk | B8: 49971 | C8: 17136 | D8: =C8/0.458 -> 37414.847 | E8: 50000 | F8: Fast | G8: Årsoppgjør faktureres senere.
A9: Kontor / rekvisita / driftsmateriale | B9: 43474 | C9: 1951 | D9: =C9/0.458 -> 4259.8253 | E9: 21000 | F9: Fast | G9: Inkl. reparasjon/vedlikehold ~13k.
A10: Telefon / internett | B10: 51214 | C10: 2902 | D10: =C10/0.458 -> 6336.2445 | E10: 51000 | F10: Fast | G10: Samme kostnad som 2025 (H1 = timing).
A11: Møte / kurs | B11: 81425 | C11: 0 | D11: =C11/0.458 -> 0 | E11: 0 | F11: Fast | G11: Bekreftet 0 i 2026.
A12: Forsikring | B12: 53847 | C12: 32018 | D12: =C12/0.458 -> 69908.297 | E12: 65000 | F12: Fast | G12: Økt i 2026 vs 2025 (54k).
A13: Bil drift (drivstoff/vedlh/annet) | B13: 32418 | C13: 6853 | D13: =C13/0.458 -> 14962.882 | E13: 25000 | F13: Fast | G13: Lavere i H1.
A14: Bank / kontingent / diverse småposter | B14: 60065 | C14: 14563 | D14: =C14/0.458 -> 31796.943 | E14: 14000 | F14: Fast | G14: Bank + kontingent ~14k
A15: Profil / arbeidsklær | B15: 0 | C15: 16678 | D15: =C15/0.458 -> 36414.847 | E15: 16000 | F15: Engangs | G15: Ny i 2026. Engangspreget.
A16: Inventar (lumpy capex) | B16: 205770 | C16: 29701 | D16: =C16/0.458 -> 64849.345 | E16: 30000 | F16: Engangs | G16: 2025 oppblåst. Normalisert avsetning.
A17: Sum faste overhead | E17: =SUM(E5:E16) -> 1107000
A18: PERSONELL FAST (ikke provisjon)
A19: Philip fastlønn (13k/mnd + arb.giver) | B19: 200000 | C19: 0 | D19: =C19/0.458 -> 0 | E19: 200000 | F19: Fast | G19: Fast del. Hans per-oppdrag foto ligger i Markedskost (Foto: Philip).
A20: Marte (fast, inkl. arb.giver) | B20: 0 | C20: 0 | D20: =C20/0.458 -> 0 | E20: 385000 | F20: Henrik | G20: 2026 DELÅR ~8 mnd (oppstart mai). Helår = 575k. Bonus 4% av Henriks oms = variabel.
A21: AVSKRIVNING (ikke-kontant)
A22: Avskrivning (saldo) | B22: 228123 | C22: 23064 | D22: =C22/0.458 -> 50358.079 | E22: 228000 | F22: Avskr | G22: 228k planlagt (maksimert saldo).
A23: MARKEDSKOST (variabel — per oppdrag inn)
A24: Foto: Philip (fakturert per oppdrag) | B24: 146930 | C24: 120280 | D24: =C24/0.458 -> 262620.09 | E24: 263000 | F24: Marked | G24: På toppen av 13k/mnd fastlønn. Fordeles per oppdrag via prosjektregnskap. 263k = annualisert H1 — kan være sesong-overdrevet (foto topper vår). BEKREFT.
A25: Foto: eksterne (Norheim m.fl.) | B25: 97110 | C25: 180855 | D25: =C25/0.458 -> 394879.91 | E25: 0 | F25: Marked | G25: Norheim = gamle skyldnader (2024/2025), nå oppgjort. 0,- herfra og ut.
A26: Fremmedytelse (klargjøring/kran/vask) | B26: 126936 | C26: 15035 | D26: =C26/0.458 -> 32827.511 | E26: 0 | F26: Marked | G26: Inn/ut (gjennomstrømming) → 0,-
A27: Salgskostnad (Finn m.m.) | B27: 61757 | C27: 46195 | D27: =C27/0.458 -> 100862.45 | E27: 95000 | F27: Marked | G27: Stiger med antall annonser.
A28: Reklame | B28: 42872 | C28: 0 | D28: =C28/0.458 -> 0 | E28: 30000 | F28: Marked | G28: 30k planlagt
A29: Reise / diett | B29: 107461 | C29: 33852 | D29: =C29/0.458 -> 73912.664 | E29: 50000 | F29: Marked | G29: 50k planlagt
A30: Bilgodtgjørelse | B30: 44252 | C30: 17765 | D30: =C30/0.458 -> 38788.21 | E30: 40000 | F30: Marked | G30: Visninger/befaringer.
A31: Varekjøp / frakt diverse | B31: 0 | C31: 6781 | D31: =C31/0.458 -> 14805.677 | E31: 0 | F31: Marked | G31: Inn/ut → 0,-
A32: Sum markedskost | E32: =SUM(E24:E31) -> 478000
A33: SALG-DREVET
A34: Tap på fordringer | B34: 58690 | C34: 0 | D34: =C34/0.458 -> 0 | E34: 0 | F34: Salg | G34: Bekreftet: blir det ikke i 2026.
A36: OPPSUMMERING → DRIVERE FOR GULV/BREAK-EVEN
A37: Felles faste (eks Marte) = overhead + Philip + avskrivning + tap − finans | E37: =E17+E19+E22+E34-21000 -> 1514000 | G37: Deles ÷3
A38: → per megler (÷3) | E38: =E37/3 -> 504666.67
A39: Marte (Henrik direkte, 2026 delår) | E39: =E20 -> 385000
A40: Markedskost total | E40: =E32 -> 478000
A41: Antall oppdrag inn (forventet 2026) ← BLÅ | E41: 105
...

Sheet Trakt per megler
A1: TRAKT PER MEGLER — fra FSBO-outreach til salg (HubSpot)
A2: Data hovedsakelig 2026 (acquisition-pipen + Marte er 2026). Henrik = Henrik + Marte (outreach). Sindre gjør ikke outreach. NB: befaring logges nesten ikke som aktivitet (~0) → «Valuation»-steget i pipen brukes som befaring-mål. Små tall = styringsindikator, ikke presisjonsprognose.
A4: 1) TRAKT — antall (siste ~12 mnd)
B5: Henrik + Marte | C5: Daniel | D5: Sindre
A6: FSBO outreach calls | B6: 305 | C6: 494 | D6: 51 | F6: Henrik=138+Marte 167. Sindre gjør ~ikke outreach.
A7: Pipeline A-deals (henvendelser inn) | B7: 83 | C7: 21 | D7: 23 | F7: Opportunities i Seller Acquisition.
A8: Nådde Valuation (= befaring) | B8: 23 | C8: 11 | D8: 17 | F8: Befaring-steg i CRM. Faktisk logget befaring-aktivitet ~0.
A9: Signert oppdrag | B9: 19 | C9: 11 | D9: 17 | F9: Agreement Signed.
A10: Solgt | B10: 36 | C10: 13 | D10: 11 | F10: Pipeline B Closed Won (inkl. eldre oppdrag fra gammel pipe).
A12: 2) KONVERTERINGSRATER (regnet av tallene over)
A13: Call → deal | B13: =B7/B6 -> 0.27213115 | C13: =C7/C6 -> 0.042510121 | D13: — | F13: Sindre: inbound, ikke fra calls.
A14: Deal → befaring (valuation) | B14: =B8/B7 -> 0.27710843 | C14: =C8/C7 -> 0.52380952 | D14: =D8/D7 -> 0.73913043
A15: Befaring → signert oppdrag | B15: =B9/B8 -> 0.82608696 | C15: =C9/C8 -> 1 | D15: =D9/D8 -> 1
A16: Deal → signert (samlet acquisition) | B16: =B9/B7 -> 0.22891566 | C16: =C9/C7 -> 0.52380952 | D16: =D9/D7 -> 0.73913043
A17: Tolkning: Daniel ringer mest (494) men bare 4% blir deals — til gjengjeld signerer han 52% av dem. Henrik+Marte: 27% av calls blir deals, men bare 23% signeres. Sindre (inbound) signerer 74%.
A20: 3) REVERSE-KALKULATOR — aktivitet for å nå gulvet
A21: Blå celler = juster. Mål-omsetning er default hver meglers gulv.
B22: Henrik + Marte | C22: Daniel | D22: Sindre
A23: Mål omsetning ex mva (gulv) ← BLÅ | B23: 2367000 | C23: 1176781 | D23: 1619824
A24: Snitt omsetning per solgt ← BLÅ | B24: 64767 | C24: 64767 | D24: 64767
A25: Close rate oppdrag → solgt ← BLÅ | B25: 0.6 | C25: 0.6 | D25: 0.6 | F25: Kryss-pipeline gjør faktisk rate usikker — juster. Default 60%.
A26: Antall solgt nødvendig | B26: =B23/B24 -> 36.546389 | C26: =C23/C24 -> 18.169454 | D26: =D23/D24 -> 25.010021
A27: Oppdrag inn nødvendig | B27: =B26/B25 -> 60.910649 | C27: =C26/C25 -> 30.282423 | D27: =D26/D25 -> 41.683368 | F27: Hver utløser markedskost uansett om båten selges.
A28: Befaringer nødvendig | B28: =B27/(B9/B8) -> 73.733943 | C28: =C27/(C9/C8) -> 30.282423 | D28: =D27/(D9/D8) -> 41.683368
A29: Pipeline A-deals nødvendig | B29: =B27/(B9/B7) -> 266.08336 | C29: =C27/(C9/C7) -> 57.811898 | D29: =D27/(D9/D7) -> 56.395144
A30: FSBO-calls nødvendig (per år) | B30: =B29/(B7/B6) -> 977.77621 | C30: =C29/(C7/C6) -> 1359.9561 | D30: — | F30: Sindre: inbound, ikke call-drevet.
A31: Til samm.: dagens calls (annualisert) | B31: =B6/0.46 -> 663.04348 | C31: =C6/0.46 -> 1073.913 | D31: —
A33: 4) DATAFORBEHOLD
A34: • Befaring logges nesten ikke som aktivitet → «Valuation»-steget brukes. Vil du ha ekte befaring-tall, må logge-disiplin opp.
A35: • Acquisition-pipen og Marte er begge 2026 → «siste 12 mnd» ≈ «2026 YTD» her. Eldre oppdrag (solgt-tallet) ligger i gammel pipe.
A36: • Signert (ny pipe) < solgt (inkl. gammel pipe) → signert→solgt-rate kan ikke leses rett av; derfor egen «close rate»-input.
A37: • Syklustid (lead→salg) er ikke trukket ut ennå (krever stegdato-historikk). Legg til ~3–5 mnd lag når du planlegger.
A38: • Små tall (11–36 per megler) → bruk som retning, ikke fasit.
