Workbook

Sheet LES MEG
A1: LES MEG — hele modellen forklart i klartekst
A4: HVA MODELLEN GJØR, I ÉN SETNING
A5: Den oversetter resultatmålet ditt (1,5M → 3M → 5M før skatt) til: hvor mange båter som må selges, hvor mange meglere det krever, hva de koster, og hva dere derfor må gjøre hver uke. Charter holdes helt utenfor.
A7: FARGEKODENE
A8: GUL celle med blå skrift = et VALG du kan endre — alt annet regner seg om automatisk.
A9: Svart skrift = utregnet av modellen. Grønn skrift = hentet fra et annet ark. Rød = et gap/avvik du skal styre på.
A11: DE FEM TALLENE SOM STYRER ALT (alle i Forutsetninger)
A12: 1. INNTEKT PER SOLGT BÅT: 58 375 kr ex mva. Målt av oppgjørslistene dine: 4 378 153 kr provisjon delt på 75 solgte båter siste 12 mnd. Vil du ha 1 million mer i omsetning, må dere selge ca. 17 båter mer — eller øke dette tallet (dyrere båter / 6 %-disiplin).
A13: 2. OMSETNING PER MEGLER-STOL: 1,5M per år for en ferdig opplært megler. Tellemåten er KREDITERT omsetning (50/50-splitt når én henter og en annen selger — det lønna følger): Henrik 1,84M, Daniel 0,88M siste 12 mnd. 1,5M er plantallet ditt.
A14: 3. MEGLERKOST: 55 øre av hver megler-krone går til megleren (40 % provisjon + arbeidsgiveravgift + feriepenger). Firmaet beholder 45 øre FØR andre kostnader.
A15: 4. KOSTBASE: 1,88M i året dekker dagens drift (Marte, Philip, kontor, systemer, avskrivning). Vokser dere, vokser den TRINNVIS (fasit-basert fra kostnadsbudsjettet): +60k per megler utover 2 (parkering/lisenser/telefon), +75k engangs per nyansettelse, +900k salgsleder ved 5, +300k kontorutvidelse ved 6 (plassholder — sjekk leieavtalen), +500k backoffice ved 8.
A16: 5. DIN EGEN LØNN: kappet på 7,1G = 969 498 kr — pensjonsopptjeningstaket; over dette lønner utbytte seg. Antas å inkludere feriepenger (12 %) → grunnlønn ≈ 865 623 (Marius bekrefter). Alt du selger utover ca. 2,15M koster ikke firmaet mer lønn — din marginale omsetning er den mest lønnsomme i selskapet.
... A47: Ukentlig drift: Weekly Scorecard (H2-rest-målet: 126 330 kr/uke). Kvartal: kvartalsmålene i Økonomimotor. Året/strategien: resultat-gapet og rekrutteringsgapet i 1-3-5 Plan. Rådgivers vurdering: H2-delen er klar til bruk; 2027–2031 er retningsgivende til trinnkostene er kalibrert og proxyene målt.

Sheet Historikk
A1: HISTORIKK — fasit, kohort og resultatbro
A2: Alt her er MÅLT (oppgjørslister/regnskap/HubSpot) — ingen mål eller antakelser. Charter holdt utenfor båt-tallene.
A4: FASIT SISTE 12 MND (oppgjørslister, 27.08.2025–26.08.2026, ex charter)
A5: Båter solgt | B5: 75
A6: Omsetning ex mva (provisjon) | B6: 4378153 | C6: alle 75 med beløp — fasit, ikke HubSpot
A7: Snitt / median per båt | B7: 58375 | C7: median 50 400
A8: Snitt / median salgssum | B8: 1260458 | C8: median 1 065 000; eff. provisjonsgrad 5,79 % inkl mva
A9: Charter (egen enhet, utenfor motoren) | B9: 170000 | C9: 1 oppdrag (AD Astra)
A11: PER MEGLER — TRE MÅTER Å TELLE (alle fra oppgjørslistene)
A12: OPPDRAG INN = hvem hentet oppdraget · SOLGT AV = hvem lukket salget · KREDITERT = 50/50-splitt ved samarbeid — det lønna følger, og det stol-tallene i modellen bruker.
A13: Megler | B13: Kreditert 12 mnd | C13: Solgt av 12 mnd | D13: Kreditert 2025 | E13: Solgt av 2025 | F13: Oppdrag inn 2025
A14: Henrik (+Marte) | B14: 1838820 | C14: 2007420 | D14: 1599192 | E14: 1962912 | F14: 1156272
A15: Sindre | B15: 1491253 | C15: 1309453 | D15: 2083205 | E15: 1597805 | F15: 2532605
A16: Daniel (slutter) | B16: 882480 | C16: 953280 | D16: 532320 | E16: 570000 | F16: 494640
A17: Jeanette (sluttet) | B17: 165600 | C17: 108000 | D17: 642800 | E17: 726800 | F17: 674000
A18: Sum | B18: =SUM(B14:B17) | C18: =SUM(C14:C17) | D18: =SUM(D14:D17) | E18: =SUM(E14:E17) | F18: =SUM(F14:F17)
A19: Sindre er ANSKAFFELSESMOTOREN (2,5M i oppdrag inn 2025), Henrik er LUKKEMOTOREN (2,0M solgt av) — ~630k av Henriks salg i 2025 var Sindres oppdrag (delt 50/50 i oppgjøret).
A20: RAMP-EMPIRI: Henrik startet mars 2025 → år 1 KREDITERT 1 599 192 (1,9M-rate, delvis ved å lukke Sindres oppdrag). Daniel startet april 2025 → år 1 kreditert 532 320 (0,71M-rate).
A21: → Ramp er PERSONDREVET, ikke tidsdrevet — og kan AKSELERERES ved at Sindre mater nye meglere med oppdrag, slik Henrik fikk i 2025. Snitt år 1-rate ≈ 1,3M kreditert (n=2, enorm spredning); churn-bufferen dekker Daniel-utfallet.
A23: KOHORT: SIGNERT OPPDRAG → SOLGT (HubSpot Pipeline B, 163 oppdrag siden sep 2024)
A24: B-deal opprettet = PROXY for signeringsdato. Closedate delvis bulk-satt (noen umulige salgstider) → indikativt.
A25: Signert kvartal | B25: n | C25: Solgt | D25: Tapt | E25: Åpne | F25: Solgt ≤90 dg | G25: Solgt ≤180 dg | H25: Median dager
A26: 2025-Q1 | B26: 11 | C26: 11 | D26: 0 | E26: 0 | F26: 4 | G26: 8 | H26: 106
A27: 2025-Q2 | B27: 32 | C27: 20 | D27: 8 | E27: 4 | F27: 9 | G27: 16 | H27: 95
A28: 2025-Q3 | B28: 25 | C28: 18 | D28: 0 | E28: 7 | F28: 6 | G28: 9 | H28: 189
A29: 2025-Q4 | B29: 11 | C29: 5 | D29: 5 | E29: 1 | F29: 1 | G29: 4 | H29: 143
A30: 2026-Q1 | B30: 18 | C30: 9 | D30: 1 | E30: 8 | F30: 4 | G30: 9 | H30: 116
A31: 2026-Q2 | B31: 49 | C31: 19 | D31: 2 | E31: 28 | F31: 17 | G31: 19 | H31: 47
A32: 2026-Q3 | B32: 16 | C32: 2 | D32: 0 | E32: 14 | F32: 2 | G32: 2 | H32: (datofeil)
A34: MODNE kohorter (signert >365 dg siden, n=58) | B34: 72 % solgt · 14 % tapt · 14 % fortsatt åpne
A35: → Signerte oppdrag per salg (modne) | B35: 58/42 = 1,38 (hvis alle 8 åpne selges: 58/50 = 1,16)
A36: Salgstid (85 solgte av 163 oppdrag sep-24→nå) | B36: median 89 dg · snitt 123 dg · 51 % ≤90 · 79 % ≤180. NB: annen kilde/periode (HubSpot, 24 mnd) enn fasitens 75 siste 12 mnd
A38: PIPELINE A — OPPDRAG INN (HubSpot, siste 12 mnd per 26.08.2026)
A39: Nye prospects (deals opprettet) | B39: 133
A40: Signert oppdragsavtale (Vunnet) | B40: 67
A41: Tapt | B41: 32
A42: Fortsatt åpne | B42: 34
A43: Vinnrate av avgjorte (67/99) — PROXY | B43: 0.68 | C43: Prospect→befaring per megler (CFO-analyse): Sindre 74 % · Daniel 52 % · Henrik+Marte 28 %
A45: RESULTATBRO 2025 — fra regnskap til modell (avstem «rest» med Marius)
A46: Sum driftsinntekter, årsregnskap 2025 | B46: 6174978 | C46: Endelig årsregnskap, signert 16.06.26
...

Sheet Økonomimotor
A1: ØKONOMIMOTOR — bemanning → kapasitet → resultat, mot målet
A2: v3: motoren regner nå BEGGE veier. Ned: planlagt bemanning (m/ramp) → kapasitet → P&L → resultat → GAP mot mål.
A3: Referanse nederst: hvilken omsetning målet KREVER (med samme trinnvise kostbase).
B5: Målt siste 12 mnd | C5: År 1 (2027) | D5: År 3 (2029) | E5: År 5 (2031)
A6: INPUT
A7: Resultatmål før skatt [målt = regnskap 2025] | B7: 736978 | C7: 1500000 | D7: 3000000 | E7: 5000000
A8: Sindre-stolens omsetning | B8: 1491253 | C8: =Forutsetninger!$B$14 | D8: =Forutsetninger!$B$14 | E8: =Forutsetninger!$B$14
A9: BEMANNINGSPLAN (PLANANTAKELSE — juster og se resultatet endre seg)
A10: Rampede megler-stoler ved årets start | B10: 1 | C10: 2 | D10: 6 | E10: 9
A11: Nyansettelser Q1 (fra kvartalets start) | B11: 0 | C11: 1 | D11: 1 | E11: 1
A12: Nyansettelser Q2 | B12: 0 | C12: 1 | D12: 1 | E12: 1
A13: Nyansettelser Q3 | B13: 0 | C13: 1 | D13: 0 | E13: 0
A14: Nyansettelser Q4 | B14: 0 | C14: 0 | D14: 0 | E14: 0
A15: EFFEKTIVE producing megler-FTE i året (ramp-vektet) | B15: 1 | C15: =C10+C11*((3*Forutsetninger!$B$20+3*Forutsetninger!$B$21+6*Forutsetninger!$B$22)/12)+C12*((3*Forutsetninger!$B$20+3*Forutsetninger!$B$21+3*Forutsetninger!$B$22)/12)+C13*((3*Forutsetninger!$B$20+3*Forutsetninger!$B$21)/12)+C14*((3*Forutsetninger!$B$20)/12) | D15: =D10+D11*((3*Forutsetninger!$B$20+3*Forutsetninger!$B$21+6*Forutsetninger!$B$22)/12)+D12*((3*Forutsetninger!$B$20+3*Forutsetninger!$B$21+3*Forutsetninger!$B$22)/12)+D13*((3*Forutsetninger!$B$20+3*Forutsetninger!$B$21)/12)+D14*((3*Forutsetninger!$B$20)/12) | E15: =E10+E11*((3*Forutsetninger!$B$20+3*Forutsetninger!$B$21+6*Forutsetninger!$B$22)/12)+E12*((3*Forutsetninger!$B$20+3*Forutsetninger!$B$21+3*Forutsetninger!$B$22)/12)+E13*((3*Forutsetninger!$B$20+3*Forutsetninger!$B$21)/12)+E14*((3*Forutsetninger!$B$20)/12)
A16: MEGLER-STOLER bemannet ved årets slutt | B16: 1 | C16: =C10+SUM(C11:C14) | D16: =D10+SUM(D11:D14) | E16: =E10+SUM(E11:E14)
A17: Gjennomsnittlig bemannede stoler i året (Q1-ansatt teller 100 %, Q2 75 %, Q3 50 %, Q4 25 %) | B17: 1 | C17: =C10+C11*1+C12*0.75+C13*0.5+C14*0.25 | D17: =D10+D11*1+D12*0.75+D13*0.5+D14*0.25 | E17: =E10+E11*1+E12*0.75+E13*0.5+E14*0.25
A18: TRINNVIS KOSTBASE (fasit-basert: 60k/stol + 75k engangs per ansettelse + terskler 5/6/8 på årets slutt)
A19: Kostbase i året, ekskl. markedskost | B19: =Forutsetninger!$B$25+MAX(0,B17-2)*Forutsetninger!$B$26+SUM(B11:B14)*Forutsetninger!$B$27+IF(B16>=5,Forutsetninger!$B$29,0)+IF(B16>=6,Forutsetninger!$B$28,0)+IF(B16>=8,Forutsetninger!$B$30,0) | C19: =Forutsetninger!$B$25+MAX(0,C17-2)*Forutsetninger!$B$26+SUM(C11:C14)*Forutsetninger!$B$27+IF(C16>=5,Forutsetninger!$B$29,0)+IF(C16>=6,Forutsetninger!$B$28,0)+IF(C16>=8,Forutsetninger!$B$30,0) | D19: =Forutsetninger!$B$25+MAX(0,D17-2)*Forutsetninger!$B$26+SUM(D11:D14)*Forutsetninger!$B$27+IF(D16>=5,Forutsetninger!$B$29,0)+IF(D16>=6,Forutsetninger!$B$28,0)+IF(D16>=8,Forutsetninger!$B$30,0) | E19: =Forutsetninger!$B$25+MAX(0,E17-2)*Forutsetninger!$B$26+SUM(E11:E14)*Forutsetninger!$B$27+IF(E16>=5,Forutsetninger!$B$29,0)+IF(E16>=6,Forutsetninger!$B$28,0)+IF(E16>=8,Forutsetninger!$B$30,0)
A20: KAPASITET → RESULTAT (P&L på planlagt bemanning)
A21: Kapasitets-omsetning ex mva (FTE × stol + Sindre) | B21: 4378153 | C21: =C15*Forutsetninger!$B$13+C8 | D21: =D15*Forutsetninger!$B$13+D8 | E21: =E15*Forutsetninger!$B$13+E8
A22: Båter solgt (omsetning ÷ inntekt per båt) | B22: 75 | C22: =C21/Forutsetninger!$B$5 | D22: =D21/Forutsetninger!$B$5 | E22: =E21/Forutsetninger!$B$5
A23: Signerte oppdrag inn (båter × 1,30 — planantakelse) | B23: 67 | C23: =C22*Forutsetninger!$B$41 | D23: =D22*Forutsetninger!$B$41 | E23: =E22*Forutsetninger!$B$41
A24: − Meglerkost inkl. AGA/feriepenger (55 % av megler-oms) | B24: =-Forutsetninger!$B$34*(B21-B8) | C24: =-Forutsetninger!$B$34*(C21-C8) | D24: =-Forutsetninger!$B$34*(D21-D8) | E24: =-Forutsetninger!$B$34*(E21-E8)
A25: − Sindre-kompensasjon (min av 45 % og 7,1G, loaded) | B25: =-MIN(Forutsetninger!$B$37*B8,Forutsetninger!$B$36)*Forutsetninger!$B$38 | C25: =-MIN(Forutsetninger!$B$37*C8,Forutsetninger!$B$36)*Forutsetninger!$B$38 | D25: =-MIN(Forutsetninger!$B$37*D8,Forutsetninger!$B$36)*Forutsetninger!$B$38 | E25: =-MIN(Forutsetninger!$B$37*E8,Forutsetninger!$B$36)*Forutsetninger!$B$38
A26: − Markedskost (per signert oppdrag × oppdrag inn) | B26: =-Forutsetninger!$B$31*B23 | C26: =-Forutsetninger!$B$31*C23 | D26: =-Forutsetninger!$B$31*D23 | E26: =-Forutsetninger!$B$31*E23
A27: − Kostbase (trinnvis, rad 19) | B27: =-B19 | C27: =-C19 | D27: =-D19 | E27: =-E19
A28: RESULTAT med planlagt bemanning | B28: =B21+SUM(B24:B27) | C28: =C21+SUM(C24:C27) | D28: =D21+SUM(D24:D27) | E28: =E21+SUM(E24:E27)
A29: GAP mot resultatmål (negativt = mangler) | C29: =C28-C7 | D29: =D28-D7 | E29: =E28-E7
A30: Implisert nettomargin (informativ) | B30: =B28/B21 | C30: =C28/C21 | D30: =D28/D21 | E30: =E28/E21
A32: KVARTALSMÅL 2027 (regnet av bemanningsplanen for år 1 — rampen synlig)
B33: Q1 2027 | C33: Q2 2027 | D33: Q3 2027 | E33: Q4 2027
A34: Producing FTE i kvartalet | B34: =C10+C11*Forutsetninger!$B$20 | C34: =C10+C11*Forutsetninger!$B$21+C12*Forutsetninger!$B$20 | D34: =C10+C11*Forutsetninger!$B$22+C12*Forutsetninger!$B$21+C13*Forutsetninger!$B$20 | E34: =C10+C11*Forutsetninger!$B$22+C12*Forutsetninger!$B$22+C13*Forutsetninger!$B$21+C14*Forutsetninger!$B$20
A35: Omsetningsmål ex mva (FTE × stol/4 + Sindre/4) | B35: =(B34*Forutsetninger!$B$13+Forutsetninger!$B$14)/4 | C35: =(C34*Forutsetninger!$B$13+Forutsetninger!$B$14)/4 | D35: =(D34*Forutsetninger!$B$13+Forutsetninger!$B$14)/4 | E35: =(E34*Forutsetninger!$B$13+Forutsetninger!$B$14)/4
A36: Båter solgt | B36: =B35/Forutsetninger!$B$5 | C36: =C35/Forutsetninger!$B$5 | D36: =D35/Forutsetninger!$B$5 | E36: =E35/Forutsetninger!$B$5
A37: Signerte oppdrag inn | B37: =B36*Forutsetninger!$B$41 | C37: =C36*Forutsetninger!$B$41 | D37: =D36*Forutsetninger!$B$41 | E37: =E36*Forutsetninger!$B$41
A38: Kontroll: snittet av de fire kvartals-FTE-ene = årets FTE i rad 15. Summen av kvartalsomsetningen = rad 21 for år 1.
A40: BEHOV FOR MÅLET — selvkonsistent kostbase (flere stoler → høyere kostbase → mer omsetning …)
A41: Kostbasen avhenger av antall stoler, som avhenger av omsetningen. Fire scenarioer — modellen velger det som er konsistent med sitt eget stol-antall. (Steady-state: engangs rekrutteringskost holdes utenfor.)
A42: Scenario A (≤4 stoler): nødvendig megler-oms | C42: =(C7+Forutsetninger!$B$25-2*Forutsetninger!$B$26-(C8-MIN(Forutsetninger!$B$37*C8,Forutsetninger!$B$36)*Forutsetninger!$B$38-(Forutsetninger!$B$31*Forutsetninger!$B$41/Forutsetninger!$B$5)*C8))/(1-Forutsetninger!$B$34-(Forutsetninger!$B$31*Forutsetninger!$B$41/Forutsetninger!$B$5)-Forutsetninger!$B$26/Forutsetninger!$B$13) | D42: =(D7+Forutsetninger!$B$25-2*Forutsetninger!$B$26-(D8-MIN(Forutsetninger!$B$37*D8,Forutsetninger!$B$36)*Forutsetninger!$B$38-(Forutsetninger!$B$31*Forutsetninger!$B$41/Forutsetninger!$B$5)*D8))/(1-Forutsetninger!$B$34-(Forutsetninger!$B$31*Forutsetninger!$B$41/Forutsetninger!$B$5)-Forutsetninger!$B$26/Forutsetninger!$B$13) | E42: =(E7+Forutsetninger!$B$25-2*Forutsetninger!$B$26-(E8-MIN(Forutsetninger!$B$37*E8,Forutsetninger!$B$36)*Forutsetninger!$B$38-(Forutsetninger!$B$31*Forutsetninger!$B$41/Forutsetninger!$B$5)*E8))/(1-Forutsetninger!$B$34-(Forutsetninger!$B$31*Forutsetninger!$B$41/Forutsetninger!$B$5)-Forutsetninger!$B$26/Forutsetninger!$B$13)
A43: → producing FTE-behov A | C43: =C42/Forutsetninger!$B$13 | D43: =D42/Forutsetninger!$B$13 | E43: =E42/Forutsetninger!$B$13
...

Sheet 1-3-5 Plan
A1: HOUSE OF YACHTS — 1/3/5-ÅRSPLAN
A2: North Star: resultat før skatt (etter Sindre-lønn kappet på 7,1G). Mål og bemanning settes i Økonomimotor.
A3: Planen handler om stoler, ikke navn. Stol = rampet megler; Sindre egen stol; buffer = planlagt tom.
B5: Målt siste 12 mnd | C5: År 1 (2027) | D5: År 3 (2029) | E5: År 5 (2031)
A6: 1. NORTH STAR (fra Økonomimotor)
A7: Resultatmål før skatt | B7: =Økonomimotor!B7 | C7: =Økonomimotor!C7 | D7: =Økonomimotor!D7 | E7: =Økonomimotor!E7
A8: Omsetning målet krever (behov) | B8: =Økonomimotor!B21 | C8: =Økonomimotor!C51 | D8: =Økonomimotor!D51 | E8: =Økonomimotor!E51
A9: Kapasitet med planlagt bemanning | C9: =Økonomimotor!C21 | D9: =Økonomimotor!D21 | E9: =Økonomimotor!E21
A10: Resultat med planlagt bemanning / GAP mot mål | B10: =Økonomimotor!B28 | C10: =Økonomimotor!C29 | D10: =Økonomimotor!D29 | E10: =Økonomimotor!E29
A12: 2. FRA OMSETNING TIL BÅTER (behov)
A13: Inntekt per solgt båt, ex mva (fasit) | B13: =Forutsetninger!$B$5 | C13: =Forutsetninger!$B$5 | D13: =Forutsetninger!$B$5 | E13: =Forutsetninger!$B$5
A14: Båter som må selges per år | B14: 75 | C14: =C8/Forutsetninger!$B$5 | D14: =D8/Forutsetninger!$B$5 | E14: =E8/Forutsetninger!$B$5
A15: Båter per måned | B15: =B14/12 | C15: =C14/12 | D15: =D14/12 | E15: =E14/12
A17: 3. FRA BÅTER TIL STOLER
A18: Producing megler-FTE målet krever | C18: =Økonomimotor!C52 | D18: =Økonomimotor!D52 | E18: =Økonomimotor!E52
A19: Planlagt producing FTE (bemanningsplan m/ramp) | B19: 1 | C19: =Økonomimotor!C15 | D19: =Økonomimotor!D15 | E19: =Økonomimotor!E15
A20: Megler-stoler å bemanne for målet (rundet opp + buffer) | C20: =Økonomimotor!C53 | D20: =Økonomimotor!D53 | E20: =Økonomimotor!E53
A21: Planlagt bemannet ved årets slutt | B21: =Forutsetninger!$B$17 | C21: =Økonomimotor!C16 | D21: =Økonomimotor!D16 | E21: =Økonomimotor!E16
A22: REKRUTTERINGSGAP mot målet (stoler) | C22: =C20-C21 | D22: =D20-D21 | E22: =E20-E21
A24: 4. FRA STOLER TIL UKENTLIGE AKTIVITETER (behov; 68 % er PROXY)
A25: Signerte oppdrag inn per år (båter × 1,30 planantakelse) | B25: 67 | C25: =C14*Forutsetninger!$B$41 | D25: =D14*Forutsetninger!$B$41 | E25: =E14*Forutsetninger!$B$41
A26: Signerte oppdrag per uke | B26: =B25/Forutsetninger!$B$44 | C26: =C25/Forutsetninger!$B$44 | D26: =D25/Forutsetninger!$B$44 | E26: =E25/Forutsetninger!$B$44
A27: Befaringer per år (÷ 68 % PROXY-vinnrate) | B27: =B25/Forutsetninger!$B$42 | C27: =C25/Forutsetninger!$B$42 | D27: =D25/Forutsetninger!$B$42 | E27: =E25/Forutsetninger!$B$42
A28: Befaringer per uke (teamet) | B28: =B27/Forutsetninger!$B$44 | C28: =C27/Forutsetninger!$B$44 | D28: =D27/Forutsetninger!$B$44 | E28: =E27/Forutsetninger!$B$44
A29: Kvalifiserte prospects per år (÷ 50 %) | B29: 133 | C29: =C27/Forutsetninger!$B$43 | D29: =D27/Forutsetninger!$B$43 | E29: =E27/Forutsetninger!$B$43
A30: Nye prospects per uke (teamet) | B30: =B29/Forutsetninger!$B$44 | C30: =C29/Forutsetninger!$B$44 | D30: =D29/Forutsetninger!$B$44 | E30: =E29/Forutsetninger!$B$44
A31: Befaringer per uke PER planlagt FTE (inkl. Sindre) | B31: =B28/(B19+1) | C31: =C28/(C19+1) | D31: =D28/(D19+1) | E31: =E28/(E19+1)
A33: Når en megler slutter: rør ikke målene. Oppdater bemanningsplanen i Økonomimotor + «bemannet i dag» i Forutsetninger.
A34: Rekrutteringsgapet og resultat-gapet oppdaterer seg selv — det er de to tallene ukemøtet skal styre på.

Sheet Spaker
A1: SPAKER — samme bemanningsplan, bedre driftsøkonomi
A2: Scenario: provisjonsdisiplin ≥6 %/45k + premium-miks (snittbåt mot 1,6M), markedskost-tak, sterkere stoler (1,8M).
A4: Scenario-parametre (blå = juster):
A5: Inntekt per båt ex mva (1,6M snittbåt × 6 % ÷ 1,25) | B5: 76800
A6: Markedskost per signert oppdrag (CFO-mål) | B6: 4552
A7: Omsetning per producing megler-stol (produksjonsmål) | B7: 1800000
C9: År 1 (2027) | D9: År 3 (2029) | E9: År 5 (2031)
A10: Resultatmål (fra Økonomimotor) | C10: =Økonomimotor!C7 | D10: =Økonomimotor!D7 | E10: =Økonomimotor!E7
A11: Kapasitets-omsetning m/spakene (samme FTE, 1,8M-stoler) | C11: =Økonomimotor!C15*$B$7+Økonomimotor!C8 | D11: =Økonomimotor!D15*$B$7+Økonomimotor!D8 | E11: =Økonomimotor!E15*$B$7+Økonomimotor!E8
A12: − Meglerkost 55 % av megler-oms | C12: =-Forutsetninger!$B$34*(C11-Økonomimotor!C8) | D12: =-Forutsetninger!$B$34*(D11-Økonomimotor!D8) | E12: =-Forutsetninger!$B$34*(E11-Økonomimotor!E8)
A13: − Sindre-kompensasjon (7,1G, loaded) | C13: =-MIN(Forutsetninger!$B$37*Økonomimotor!C8,Forutsetninger!$B$36)*Forutsetninger!$B$38 | D13: =-MIN(Forutsetninger!$B$37*Økonomimotor!D8,Forutsetninger!$B$36)*Forutsetninger!$B$38 | E13: =-MIN(Forutsetninger!$B$37*Økonomimotor!E8,Forutsetninger!$B$36)*Forutsetninger!$B$38
A14: − Markedskost (oms ÷ 76 800 × 1,30 × 4 552) | B14: (færre båter per krone enn baseline!) | C14: =-$B$6*(C11/$B$5*Forutsetninger!$B$41) | D14: =-$B$6*(D11/$B$5*Forutsetninger!$B$41) | E14: =-$B$6*(E11/$B$5*Forutsetninger!$B$41)
A15: − Kostbase (samme trinnkost som motoren, rad 19) | C15: =-Økonomimotor!C19 | D15: =-Økonomimotor!D19 | E15: =-Økonomimotor!E19
A16: RESULTAT m/spakene på planlagt bemanning | C16: =C11+SUM(C12:C15) | D16: =D11+SUM(D12:D15) | E16: =E11+SUM(E12:E15)
A17: KONTROLL: linjene minus resultat (skal være 0) | C17: =(C11+C12+C13+C14+C15)-C16 | D17: =(D11+D12+D13+D14+D15)-D16 | E17: =(E11+E12+E13+E14+E15)-E16
A18: Resultat baseline (Økonomimotor) | C18: =Økonomimotor!C28 | D18: =Økonomimotor!D28 | E18: =Økonomimotor!E28
A19: Spak-effekt på resultatet | C19: =C16-C18 | D19: =D16-D18 | E19: =E16-E18
A21: BEHOV FOR MÅLET M/SPAKENE — selvkonsistent, samme metode som motoren. NB: FTE = produksjonskapasitet, IKKE personer.
A22: Scenario A (≤4 bemannede): nødvendig megler-oms | C22: =(Økonomimotor!C7+Forutsetninger!$B$25-2*Forutsetninger!$B$26-(Økonomimotor!C8-MIN(Forutsetninger!$B$37*Økonomimotor!C8,Forutsetninger!$B$36)*Forutsetninger!$B$38-($B$6*Forutsetninger!$B$41/$B$5)*Økonomimotor!C8))/(1-Forutsetninger!$B$34-($B$6*Forutsetninger!$B$41/$B$5)-Forutsetninger!$B$26/$B$7) | D22: =(Økonomimotor!D7+Forutsetninger!$B$25-2*Forutsetninger!$B$26-(Økonomimotor!D8-MIN(Forutsetninger!$B$37*Økonomimotor!D8,Forutsetninger!$B$36)*Forutsetninger!$B$38-($B$6*Forutsetninger!$B$41/$B$5)*Økonomimotor!D8))/(1-Forutsetninger!$B$34-($B$6*Forutsetninger!$B$41/$B$5)-Forutsetninger!$B$26/$B$7) | E22: =(Økonomimotor!E7+Forutsetninger!$B$25-2*Forutsetninger!$B$26-(Økonomimotor!E8-MIN(Forutsetninger!$B$37*Økonomimotor!E8,Forutsetninger!$B$36)*Forutsetninger!$B$38-($B$6*Forutsetninger!$B$41/$B$5)*Økonomimotor!E8))/(1-Forutsetninger!$B$34-($B$6*Forutsetninger!$B$41/$B$5)-Forutsetninger!$B$26/$B$7)
A23: → producing FTE-behov A | C23: =C22/$B$7 | D23: =D22/$B$7 | E23: =E22/$B$7
A24: Scenario B (5 bemannede, +leder): megler-oms | C24: =(Økonomimotor!C7+Forutsetninger!$B$25-2*Forutsetninger!$B$26-(Økonomimotor!C8-MIN(Forutsetninger!$B$37*Økonomimotor!C8,Forutsetninger!$B$36)*Forutsetninger!$B$38-($B$6*Forutsetninger!$B$41/$B$5)*Økonomimotor!C8)+Forutsetninger!$B$29)/(1-Forutsetninger!$B$34-($B$6*Forutsetninger!$B$41/$B$5)-Forutsetninger!$B$26/$B$7) | D24: =(Økonomimotor!D7+Forutsetninger!$B$25-2*Forutsetninger!$B$26-(Økonomimotor!D8-MIN(Forutsetninger!$B$37*Økonomimotor!D8,Forutsetninger!$B$36)*Forutsetninger!$B$38-($B$6*Forutsetninger!$B$41/$B$5)*Økonomimotor!D8)+Forutsetninger!$B$29)/(1-Forutsetninger!$B$34-($B$6*Forutsetninger!$B$41/$B$5)-Forutsetninger!$B$26/$B$7) | E24: =(Økonomimotor!E7+Forutsetninger!$B$25-2*Forutsetninger!$B$26-(Økonomimotor!E8-MIN(Forutsetninger!$B$37*Økonomimotor!E8,Forutsetninger!$B$36)*Forutsetninger!$B$38-($B$6*Forutsetninger!$B$41/$B$5)*Økonomimotor!E8)+Forutsetninger!$B$29)/(1-Forutsetninger!$B$34-($B$6*Forutsetninger!$B$41/$B$5)-Forutsetninger!$B$26/$B$7)
A25: → producing FTE-behov B | C25: =C24/$B$7 | D25: =D24/$B$7 | E25: =E24/$B$7
A26: Scenario C (6–7, +leder+kontor): megler-oms | C26: =(Økonomimotor!C7+Forutsetninger!$B$25-2*Forutsetninger!$B$26-(Økonomimotor!C8-MIN(Forutsetninger!$B$37*Økonomimotor!C8,Forutsetninger!$B$36)*Forutsetninger!$B$38-($B$6*Forutsetninger!$B$41/$B$5)*Økonomimotor!C8)+Forutsetninger!$B$29+Forutsetninger!$B$28)/(1-Forutsetninger!$B$34-($B$6*Forutsetninger!$B$41/$B$5)-Forutsetninger!$B$26/$B$7) | D26: =(Økonomimotor!D7+Forutsetninger!$B$25-2*Forutsetninger!$B$26-(Økonomimotor!D8-MIN(Forutsetninger!$B$37*Økonomimotor!D8,Forutsetninger!$B$36)*Forutsetninger!$B$38-($B$6*Forutsetninger!$B$41/$B$5)*Økonomimotor!D8)+Forutsetninger!$B$29+Forutsetninger!$B$28)/(1-Forutsetninger!$B$34-($B$6*Forutsetninger!$B$41/$B$5)-Forutsetninger!$B$26/$B$7) | E26: =(Økonomimotor!E7+Forutsetninger!$B$25-2*Forutsetninger!$B$26-(Økonomimotor!E8-MIN(Forutsetninger!$B$37*Økonomimotor!E8,Forutsetninger!$B$36)*Forutsetninger!$B$38-($B$6*Forutsetninger!$B$41/$B$5)*Økonomimotor!E8)+Forutsetninger!$B$29+Forutsetninger!$B$28)/(1-Forutsetninger!$B$34-($B$6*Forutsetninger!$B$41/$B$5)-Forutsetninger!$B$26/$B$7)
A27: → producing FTE-behov C | C27: =C26/$B$7 | D27: =D26/$B$7 | E27: =E26/$B$7
A28: Scenario D (≥8, +leder+kontor+backoffice): megler-oms | C28: =(Økonomimotor!C7+Forutsetninger!$B$25-2*Forutsetninger!$B$26-(Økonomimotor!C8-MIN(Forutsetninger!$B$37*Økonomimotor!C8,Forutsetninger!$B$36)*Forutsetninger!$B$38-($B$6*Forutsetninger!$B$41/$B$5)*Økonomimotor!C8)+Forutsetninger!$B$29+Forutsetninger!$B$28+Forutsetninger!$B$30)/(1-Forutsetninger!$B$34-($B$6*Forutsetninger!$B$41/$B$5)-Forutsetninger!$B$26/$B$7) | D28: =(Økonomimotor!D7+Forutsetninger!$B$25-2*Forutsetninger!$B$26-(Økonomimotor!D8-MIN(Forutsetninger!$B$37*Økonomimotor!D8,Forutsetninger!$B$36)*Forutsetninger!$B$38-($B$6*Forutsetninger!$B$41/$B$5)*Økonomimotor!D8)+Forutsetninger!$B$29+Forutsetninger!$B$28+Forutsetninger!$B$30)/(1-Forutsetninger!$B$34-($B$6*Forutsetninger!$B$41/$B$5)-Forutsetninger!$B$26/$B$7) | E28: =(Økonomimotor!E7+Forutsetninger!$B$25-2*Forutsetninger!$B$26-(Økonomimotor!E8-MIN(Forutsetninger!$B$37*Økonomimotor!E8,Forutsetninger!$B$36)*Forutsetninger!$B$38-($B$6*Forutsetninger!$B$41/$B$5)*Økonomimotor!E8)+Forutsetninger!$B$29+Forutsetninger!$B$28+Forutsetninger!$B$30)/(1-Forutsetninger!$B$34-($B$6*Forutsetninger!$B$41/$B$5)-Forutsetninger!$B$26/$B$7)
A29: → producing FTE-behov D | C29: =C28/$B$7 | D29: =D28/$B$7 | E29: =E28/$B$7
A30: ENDELIG nødvendig total omsetning m/spakene | B30: (konsistent scenario) | C30: =IF(ROUNDUP(C23,0)<=4,C22,IF(ROUNDUP(C25,0)<=5,C24,IF(ROUNDUP(C27,0)<=7,C26,C28)))+Økonomimotor!C8 | D30: =IF(ROUNDUP(D23,0)<=4,D22,IF(ROUNDUP(D25,0)<=5,D24,IF(ROUNDUP(D27,0)<=7,D26,D28)))+Økonomimotor!D8 | E30: =IF(ROUNDUP(E23,0)<=4,E22,IF(ROUNDUP(E25,0)<=5,E24,IF(ROUNDUP(E27,0)<=7,E26,E28)))+Økonomimotor!E8
A31: ENDELIG producing FTE-behov m/spakene | C31: =(C30-Økonomimotor!C8)/$B$7 | D31: =(D30-Økonomimotor!D8)/$B$7 | E31: =(E30-Økonomimotor!E8)/$B$7
A32: Bemannede meglere, steady-state (rundet opp) | B32: (rampede — i INNFASINGSÅR trengs flere pga ramp) | C32: =ROUNDUP(C31,0) | D32: =ROUNDUP(D31,0) | E32: =ROUNDUP(E31,0)
A33: Producing FTE-behov baseline (Økonomimotor) | C33: =Økonomimotor!C52 | D33: =Økonomimotor!D52 | E33: =Økonomimotor!E52
A36: DE FIRE SPAKENE (CFO-analysen jul 2026) — verdt å hente FØR flere stoler rekrutteres:
A37: A. Provisjonsdisiplin: 13 av 38 H1-salg under 6 %/45k = ~266k tapt provisjon. Rabatt krever Sindres godkjenning. ~200k+/år.
A38: B. Marte-tripwire (18. okt): Henrik må vise 1,9M+ årstakt og bedre befaring-rate. Svinger resultatet 500–700k. Status aug: behold.
A39: C. Markedskost-tak: 15k-tak håndheves; frys markedsføring over taket til pris justeres. Mål 4 552/oppdrag (målt 6 600).
A40: D. Sindres 7,1G-uttak: alt Sindre omsetter over ~2,15M koster ikke mer lønn — hans marginale omsetning er firmaets mest lønnsomme.
A41: E. (Ny) Premium-miks: fasit-snittet er 58 375/båt (median 50 400). Hver 10 000 kr høyere inntekt/båt ≈ 15–20 % færre båter for samme mål.

Sheet Likviditet
A1: LIKVIDITET — månedlig kontantstrøm jan 2027 – des 2028
A2: Samme motor som resten av boka (Forutsetninger). GUL = ditt valg. Ferske åpningstall per 28.08.2026. Alt merket ANSLAG/PLASSHOLDER kan justeres fritt.
A3: NØKKELTALL (regnes av tabellen under)
A4: Laveste kontantsaldo i perioden | B4: =MIN(B102:Y102)
A5: — inntreffer i måned | B5: =INDEX(B53:Y53,1,MATCH(MIN(B102:Y102),B102:Y102,0))
A6: Margin mot minimumsbuffer på lavpunktet | B6: =MIN(B102:Y102)-$B$29
A7: Antall måneder under bufferen | B7: =COUNTIF(B102:Y102,"<"&$B$29)
A8: Laveste saldo + kassekreditt (bunn før overtrekk) | B8: =MIN(B102:Y102)+$B$30
A9: Kontantsaldo ved utgangen (des 2028) | B9: =Y102
A11: FERSKE TALL FRA POWEROFFICE (hentet 2026-08-29 — oppdateres nattlig)
A12: Bank — PowerOffice-hovedbok (alle 19xx) | B12: -289975 | C12: AVSTEMMING: sammenlign med reell banksaldo i A. Stort avvik = uposterte bilag (hovedboka henger etter).
A13: Kundefordringer (hovedbok 15xx) | B13: 1429008 | C13: Utestående kundefordringer. Åpne poster (reell AR): 1 429 008
A14: Leverandørgjeld (24xx) | B14: -17130 | C14: Negativt = gjeld.
A15: Utgående mva-gjeld (27xx) | B15: -578155 | C15: Negativt = skyldig mva. Betales ved neste termin (i praksis i Q4 2026 — del av bro sep–des).
A16: Skyldig skattetrekk (26xx) | B16: 0 | C16: Bundet på skattetrekkskonto.
A17: Betalbar skatt (25xx) | B17: 14636
A18: Driftskost annualisert (6xxx+7xxx, u/lønn) | B18: 262779 | C18: Fra 14 mnd posteringer × 12. Lønn (5xxx) = 1 002 310 i vinduet (inkl. megler+Marte+Philip — må splittes før kostbase-kalibrering).
A19: Grønne tall hentes automatisk fra PowerOffice hver gang boka bygges. De er FERSK POSISJON i dag (28.08) — modellen starter jan 2027, så bruk dem til å sette broen sep–des 2026 og overheng, ikke som direkte januartall.
A21: A. ÅPNINGSPOSISJON OG STYRINGSVALG
A22: Hovedbok 1920 — bank (live fra PowerOffice) | B22: -289978 | C22: Bokført banksaldo (henger etter reell bank med differansen under).
A23: + Avstemmingsdifferanse (kontoutskrift − hovedbok 1920) | B23: 1360037 | C23: Fra PO bankavstemming 14.09.2026: 1 069 274 − (−290 763) = 1 360 037. Frossen historisk differanse (avstemmingen viser «Sum bevegelser 0»). Oppdater fra GO-rapporten ved behov.
A24: =Reell banksaldo (kontoutskrift) | B24: =$B$22+$B$23 | C24: =hovedbok 1920 + differanse ≈ «Saldo kontoutskrift» i GO. Oppdateres live når 1920 synkes. UTEN kassekreditt (se under).
A25: — herav bundet skattetrekk (utilgjengelig) | B25: 0 | C25: Auto fra PowerOffice (konto 26xx).
A26: Disponibel saldo i dag | B26: =$B$24-$B$25
A27: Netto driftskontantstrøm sep–des 2026 (bro til nyttår) | B27: 0 | C27: PLASSHOLDER. Netto inn−ut sep–des 2026 EKSKL. provisjon som først innbetales i 2027 (ligger i «overheng» under).
A28: =ÅPNINGSSALDO 1. jan 2027 | B28: =$B$26+$B$27
A29: Minimumsbuffer (ønsket bunnivå på konto) | B29: 500000 | C29: Ditt valg. Modellen flagger måneder under dette.
A30: Tilgjengelig kassekreditt (overtrekksramme) | B30: 200000 | C30: Ekstra likviditet på toppen — kontoutskrift-saldoen er UTEN denne. Reell bunn før overtrekk = −kassekreditt.
A31: Cash-lag scenario (1=Base median ~14d · 2=Plan P75 ~32d · 3=Stress P90 ~61d) | B31: 1 | C31: DOKUMENTERT deal-for-deal (solgt→faktura, n=92, se deal-for-deal-oppgjor.csv): median 14d, P75 32d, P90 61d, maks 116. Andel betalt innen 7/14/30/60d = 23/51/75/89 %. FOR ANSETTELSESBESLUTNINGER: bruk Plan (P75=2). NB (rådgiver): fakturadato brukes som OPERATIV cash-proxy fordi provisjonen normalt er tilgjengelig ved oppgjør — dette må avstemmes mot FAKTISK bankdato. Bokført betalt ligger i flere tilfeller 50–100 d etter faktura (bevis bokføringsetterslep, ikke at cash var tilgjengelig samme dag). Hent bankdato for de store oppgjørene.
A32: Sesongprofil på salg (1=empirisk · 0=flatt 1/12) | B32: 1 | C32: 1 = fordel salget som FAKTISK målt (mai–jul tungt, vinter tynt). 0 = jevnt.
A33: Markedsføring betales N mnd FØR salget | B33: 3 | C33: Annonsering/foto betales når oppdraget signeres, ~89 dg (3 mnd) før salg.
A34: Meglerutbetaling N mnd etter salg | B34: 0 | C34: 0 = megler får oppgjør samme måned som salget (konservativt).
A35: Mva-sats (utgående/inngående) | B35: 0.25 | C35: Standard 25 %.
A36: Mva-belagt andel av kostbasen | B36: 0.35 | C36: PLANANTAKELSE: andel av kostbasen (ekskl. lønn) med inngående mva.
A38: B. BETALINGSPROFIL — andel av en salgsmåneds provisjon innbetalt m/forsinkelse
A39: Profil | B39: salgsmnd | C39: +1 mnd | D39: +2 mnd | E39: +3 mnd | F39: +4 mnd | G39: snitt (dg)
A40: 1 Base — faktisk median (~14d) | B40: 0.54 | C40: 0.3 | D40: 0.1 | E40: 0.03 | F40: 0.03 | G40: =(C40*1+D40*2+E40*3+F40*4)*30.4
A41: 2 Plan — P75 (~32d) | B41: 0.3 | C41: 0.4 | D41: 0.2 | E41: 0.07 | F41: 0.03 | G41: =(C41*1+D41*2+E41*3+F41*4)*30.4
A42: 3 Stress — P90 (~61d) | B42: 0.1 | C42: 0.25 | D42: 0.4 | E42: 0.2 | F42: 0.05 | G42: =(C42*1+D42*2+E42*3+F42*4)*30.4
A43: AKTIV PROFIL (valgt av scenario over) | B43: =CHOOSE($B$31,B40,B41,B42) | C43: =CHOOSE($B$31,C40,C41,C42) | D43: =CHOOSE($B$31,D40,D41,D42) | E43: =CHOOSE($B$31,E40,E41,E42) | F43: =CHOOSE($B$31,F40,F41,F42) | G43: =SUM(B43:F43)
...

Sheet Forutsetninger
A1: FORUTSETNINGER — én datadefinisjon per KPI
A2: Gule celler = juster fritt (alt rekalkulerer). FASIT = oppgjørslistene («lønn solgte båter»), ikke HubSpot. Oppdatert 26.08.2026.
A4: FASIT SALG — kilde: oppgjørslister 2025+2026, solgt-dato 27.08.2025–26.08.2026, EX CHARTER
A5: Inntekt per solgt båt, ex mva (MOTOR-INPUT) | B5: 58375 | C5: DEF: sum omsetning ex mva 4 378 153 / 75 båtsalg i oppgjørslistene siste 12 mnd. Median 50 400. Alle 75 har beløp (fasit — ikke HubSpot-amount, som manglet 4 deals og ga 64 100). Charter (170k) holdt HELT utenfor.
A6: Snittbåtverdi (salgssum) — informativ | B6: 1260458 | C6: DEF: snitt salgssum i oppgjørslistene, 75/75 deals. Median 1 065 000. Brukes IKKE i motoren.
A7: Provisjonsgrad 1: standard avtalt | B7: 0.06 | C7: DEF: 6,00 % av salgssum INKL mva, min. 45 000 inkl mva (= 36 000 ex). Kontraktsstandard.
A8: Provisjonsgrad 2: målt effektiv (fasit, alle 75) | B8: 0.0579 | C8: DEF: sum(oms ex mva × 1,25) / sum(salgssum) = 5,79 % inkl mva (4,63 % ex). Teller og nevner er nå SAMME utvalg (75/75) — kontrolltallet fra v2 er dermed identisk og trengs ikke lenger. Gap til 6 % = rabatter/min.honorar.
A9: Charter — holdes utenfor motoren | B9: 170000 | C9: 1 charteroppdrag siste 12 mnd (AD Astra, 170 000 ex mva). Egen produksjonsenhet; regnes IKKE i inntekt per båt, båter/år eller stol-kapasitet.
A11: STOL-DEFINISJONER OG KAPASITET
A12: DEF «stol» | C12: Én fullt produktiv megler ETTER ramp (6–9 mnd). Sindre er ALLTID egen stol utenom. «Producing FTE» = effektiv produksjonskapasitet i året (ramp-vektet, desimal). «Bemannet» = personer på lønn. Buffer-stol = planlagt tom (rekrutteringspipeline).
A13: Omsetning per producing megler-stol (plantall) | B13: 1500000 | C13: PRODUKSJONSMÅL for rampet stol. Fasit siste 12 mnd KREDITERT (50/50 v/samarbeid — det lønna følger): Henrik 1 838 820, Sindre 1 491 253, Daniel 882 480. Solgt av: Henrik 2 007 420 (35 båter) — han lukker også andres oppdrag.
A14: Sindre-stolens omsetning per år (plantall) | B14: 2300000 | C14: CFO-anbefalt mål ~2,28M. Fasit siste 12 mnd kreditert: 1 491 253 (2025: 2 083 205) — inkl. lederrolle; han HENTET oppdrag for langt mer (2,5M inn i 2025).
A15: Break-even per ny stol (egne kostnader) | B15: =$B$26/(1-$B$34-$B$31*$B$41/$B$5) | C15: FORMEL: løpende trinnkost ÷ megler-marginal (1−0,55−markedskost-rate) ≈ 200k omsetning dekker stolens EGNE kostnader. Å dekke en ANDEL av felles faste krever ~1,2–1,7M (jf. «Lønnsomhet per megler» i kostnadsmodellen) — det er Sindres poeng om når en megler begynner å tjene penger.
A16: Churn-buffer (stoler planlagt tomme) | B16: 1 | C16: Ditt valg: planlegg alltid som om én stol står tom (Daniel-effekten).
A17: Megler-stoler bemannet i dag (utenom Sindre) | B17: 1 | C17: Henrik (+Marte som assistent). Daniel slutter → telles ikke.
A19: RAMP-PROFIL FOR NYANSATT MEGLER (PLANANTAKELSE)
A20: Produksjon måned 1–3 (andel av full stol) | B20: 0.4 | C20: EMPIRI (begge startet mars/apr 2025): Henrik solgte 1 963k i år 1 (2,35M-rate), Daniel 570k (0,76M-rate) — snitt ≈ full stol, men enorm spredning. 40/75/100 ligger bevisst under snittet av n=2.
A21: Produksjon måned 4–6 | B21: 0.75 | C21: Egen portefølje bygges. Median salgstid 89 dg → første oppgjør kommer ~3 mnd etter første oppdrag.
A22: Produksjon måned 7–12 | B22: 1 | C22: Fullt producing fra ~mnd 7. Henrik beviste at det er mulig; churn-bufferen tar høyde for en Daniel-profil.
A24: TRINNVIS KOSTBASE (PLANANTAKELSE — juster mot egne tall)
A25: Grunnkostbase per år (dekker inntil 2 megler-stoler) | B25: 1880000 | C25: DEF: kostbase fullastet 2,54M (kostnadsmodell jun 2026) minus markedskost-andelen. Inkl. Marte, Philip, avskrivning 228k, kontor, systemer — dagens nivå.
A26: Løpende tilleggskost per bemannet stol utover 2 | B26: 60000 | C26: FASIT-BASERT (kostnadsbudsjett 2026): parkering ~18k + CRM/lisenser ~30k + telefon/forsikring ~12k per hode. Kontor koster INGENTING før stol nr. 6 (plass på dagens kontor).
A27: Engangs rekrutterings-/onboardingkost per nyansettelse | B27: 75000 | C27: PLANANTAKELSE: annonsering, intervjutid, utstyr, opplæring — belastes ansettelsesåret.
A28: Kontorutvidelse fra ≥6 bemannede stoler | B28: 300000 | C28: PLASSHOLDER — dagens kontor har plass til ~5. Sjekk leieavtalen for faktisk kostnad ved utvidelse.
A29: Salgsleder/daglig-leder-kapasitet fra ≥5 stoler | B29: 900000 | C29: PLANANTAKELSE: ved 5+ meglere kan ikke Sindre både selge 2,3M og lede alene.
A30: Ekstra backoffice/administrasjon fra ≥8 stoler | B30: 500000 | C30: PLANANTAKELSE: kundeservice, oppgjør, kontor.
A31: Markedskost per signert oppdrag inn | B31: 6600 | C31: DEF: målt snitt per SIGNERT oppdrag. CFO-mål: 4 552 + 15k-tak håndheves.
A33: MEGLERKOST OG SINDRE-LØNN
A34: Meglerkost, fullastet andel av megler-omsetning | B34: 0.55 | C34: DEF: meglerprovisjon (40 %) + AGA + feriepenger ≈ 55 øre per megler-omsetningskrone.
A35: Grunnbeløpet G (per 1.5.2026) | B35: 136549 | C35: Kilde: nav.no/grunnbelopet. Oppdateres hver mai.
A36: Sindres lønnstak (7,1G) | B36: =7.1*$B$35 | C36: DEF: 7,1G = taket for pensjonsopptjening i folketrygden — over dette lønner utbytte seg. Pensjonsgivende inntekt inkluderer feriepenger.
A37: Sindres provisjonssats | B37: 0.45 | C37: 45 % av egen omsetning ex mva (før tak).
A38: Lønns-loading (AGA + feriepenger) | B38: 1.165 | C38: For Sindre: AGA/OTP-påslag. 7,1G-taket antas å INKLUDERE feriepenger (12 %, ikke 10,2) → grunnlønn ≈ 865 623 + 12 % FP = 969 498. MARIUS BEKREFTER inkl/eks-tolkningen; eks-tolkning koster ~115k mer.
A40: TRAKT — kilder: kohortanalyse (Historikk) + HubSpot Pipeline A per 26.08.2026
A41: Signerte oppdrag inn per solgt båt (PLANANTAKELSE) | B41: 1.3 | C41: KOHORTMÅLT på modne oppdrag (>365 dg, n=58): 72 % solgt → 58/42 = 1,38 oppdrag/salg; hvis alle 8 åpne til slutt selges: 58/50 = 1,16. 1,30 = planantakelse mellom. v2-tallet 1,15 forkastet (samtidighetsfeil, jf. rådgiver).
A42: Vinnrate Pipeline A — PROXY for befaring→signering | B42: 0.68 | C42: PROXY, IKKE målt close rate befaring→signering! DEF: 67 vunnet / 99 avgjorte deals i Pipeline A siste 12 mnd (hele trakten, prospect→signert). Isolert befaring→signering krever stage-historikk — mangler (mål: 90 %).
A43: Prospect → befaring-rate (plantall) | B43: 0.5 | C43: Målt per megler (CFO-analyse): Sindre 74 %, Daniel 52 %, Henrik+Marte 28 %.
A44: Arbeidsuker per år | B44: 46 | C44: Ferie/helligdager trukket fra.
A46: SCORECARD-PARAMETRE (H2 2026)
A47: H2-2026-mål omsetning ex mva (uten Daniel) | B47: 2900000 | C47: Fra revidert H2-plan aug 2026.
...

Sheet Weekly Scorecard
A1: WEEKLY SCORECARD — koblet til motoren (fyll inn hver fredag)
A2: STYR PÅ ÉN LINJE: provisjon ex mva (hovedmålet). Leading-kolonnene forklarer NESTE måneds provisjon (salgstid ~89 dg). «H2-rest» = (mål − levert)/uker igjen — oppdater ukentlig.
A3: Befaring-målet bruker 68 % PROXY-vinnrate. Rekrutteringsstatus er fast punkt i ukemøtet.
A5: Uke | B5: Nye prospects | C5: Befaringer | D5: Signerte oppdrag | E5: Båter solgt | F5: Provisjon ex mva | G5: Publisert ≤7 dg | H5: Actions neste uke | I5: R/G/G
A6: Type | B6: LEADING | C6: LEADING | D6: LEADING | E6: LAGGING | F6: ★ HOVEDMÅL | G6: KONTROLL
A7: MÅL: H2-rest (per KALENDERUKE, 17 igjen) | B7: =((Forutsetninger!$B$47-Forutsetninger!$B$48)/Forutsetninger!$B$5/Forutsetninger!$B$49)*Forutsetninger!$B$41/Forutsetninger!$B$42/Forutsetninger!$B$43 | C7: =((Forutsetninger!$B$47-Forutsetninger!$B$48)/Forutsetninger!$B$5/Forutsetninger!$B$49)*Forutsetninger!$B$41/Forutsetninger!$B$42 | D7: =((Forutsetninger!$B$47-Forutsetninger!$B$48)/Forutsetninger!$B$5/Forutsetninger!$B$49)*Forutsetninger!$B$41 | E7: =((Forutsetninger!$B$47-Forutsetninger!$B$48)/Forutsetninger!$B$5/Forutsetninger!$B$49) | F7: =(Forutsetninger!$B$47-Forutsetninger!$B$48)/Forutsetninger!$B$49 | G7: 1
A8: Info: År 1-behov 2027 (per ARBEIDSUKE av 46 — IKKE sammenlignbar med H2-linjen) | B8: ='1-3-5 Plan'!C30 | C8: ='1-3-5 Plan'!C28 | D8: ='1-3-5 Plan'!C26 | E8: ='1-3-5 Plan'!C14/Forutsetninger!$B$44 | F8: ='1-3-5 Plan'!C8/Forutsetninger!$B$44 | G8: 1
A10: 36
A11: 37
A12: 38
A13: 39
A14: 40
A15: 41
A16: 42
A17: 43
A18: 44
A19: 45
A20: 46
A21: 47
... A30: Definisjoner: Nye prospects = deals opprettet i Pipeline A. Befaringer = holdte. Signerte = Vunnet i A. Provisjon = oppgjørsliste ex mva.
